Workbook

Sheet 1D
A1: 1D Steady Open Channel Network Solver
A3: Two-pass steady 1D workbook: subcritical backwater, supercritical forewater, mixed-flow specific-force selection, and spill routing to drain.
B4: Parameter | C4: Unit | D4: Value | H4: Fundamental Inputs | K4: Boundary | L4: Segment | M4: End | N4: Type | O4: Value | P4: Resolved Stage | Q4: Remarks
B5: Total inflow Q | C5: m3/s | D5: 51 | G5: Acceleration g | H5: m/s2 | I5: 9.81 | K5: Inlet-UsProject | L5: UsProject | M5: start | N5: Known WSE | O5: 637 | P5: =IF(OR(N5="Known WSE", N5="Known WS"), O5, IF(N5="Known Depth", (J31)+(O5), IF(N5="Normal Depth", (J31)+(MAX($D$16, POWER((ABS(N31)*$D$6)/(MAX(F31, 0.1)*SQRT(MAX(ABS((K31-J31)/MAX(E31, 0.000001)), $D$17))), 3/5))), IF(N5="Critical Depth", (J31)+(MAX($D$16, POWER((ABS(N31)^2)/($I$5*MAX(F31, 0.1)^2), 1/3))), IF(OR(N5="Dead End", N5="None", N5="Spill End"), IF(O5="", (J31)+$D$16, O5), IF(N5="Spill Zero", (J31)+$D$16, (J31)+(MAX($D$16, POWER((ABS(N31)*$D$6)/(MAX(F31, 0.1)*SQRT(MAX(ABS((K31-J31)/MAX(E31, 0.000001)), $D$17))), 3/5))))))))) -> 637 | Q5: Master inlet boundary
B6: Manning n | C6: - | D6: 0.015 | G6: Density rho | H6: kg/m3 | I6: 998.2 | K6: Outlet-UsExit | L6: UsExit | M6: end | N6: Dead End | O6: 637 | P6: =IF($D$20=0, IFERROR(P6, IF(O6="", $I$13, O6)), IF($I$25=0, IFERROR(P6, IF(O6="", $I$13, O6)), IF(ABS((($I$13)-IFERROR(UsExit!AA10, $I$13)))<$D$19, IFERROR(P6, IF(O6="", $I$13, O6)), MAX((K33)+$D$16, IFERROR(P6, IF(O6="", $I$13, O6))+($D$13*((($I$13)-IFERROR(UsExit!AA10, $I$13)))))))) -> 648.78436 | Q6: Dead End outlet; dummy reach resolves downstream stage only to maintain the solved upstream junction energy.
B7: Default bank slope | C7: H:V | D7: 0 | G7: Allowed BC types | H7: - | I7: Known WSE / Known Depth / Normal Depth / Critical Depth / Dead End / Spill End / Spill Zero | K7: Outlet-forebay | L7: forebay | M7: end | N7: Spill End | O7: 635.5 | P7: =IF($D$20=0, IFERROR(P7, IF(O7="", $I$14, O7)), IF($I$26=0, IFERROR(P7, IF(O7="", $I$14, O7)), IF((MAX(0, forebay!K48-((forebay!AM48)+(forebay!AN48))-0.05))>$D$19, MAX((K34)+$D$16, IFERROR(P7, IF(O7="", $I$14, O7))+(MIN(0.05, MAX(0.005, $D$13*(MAX(0, forebay!K48-((forebay!AM48)+(forebay!AN48))-0.05))/MAX(ABS(N34), 1))))), IF(ABS((($I$14)-IFERROR(forebay!AA10, $I$14)))<$D$19, IFERROR(P7, IF(O7="", $I$14, O7)), MAX((K34)+$D$16, IFERROR(P7, IF(O7="", $I$14, O7))+($D$13*((($I$14)-IFERROR(forebay!AA10, $I$14))))))))) -> 635.5 | Q7: Spill End outlet; lateral spill is capacity-limited and the downstream stage rises when spill capacity is short.
B8: Expansion coeff Ke | C8: - | D8: 0.3 | K8: Outlet-sidechannel | L8: sidechannel | M8: end | N8: Spill End | O8: 635.5 | P8: =IF($D$20=0, IFERROR(P8, IF(O8="", $I$14, O8)), IF($I$26=0, IFERROR(P8, IF(O8="", $I$14, O8)), IF((MAX(0, sidechannel!K45-((sidechannel!AM45)+(sidechannel!AN45))-0.05))>$D$19, MAX((K35)+$D$16, IFERROR(P8, IF(O8="", $I$14, O8))+(MIN(0.05, MAX(0.005, $D$13*(MAX(0, sidechannel!K45-((sidechannel!AM45)+(sidechannel!AN45))-0.05))/MAX(ABS(N35), 1))))), IF(ABS((($I$14)-IFERROR(sidechannel!AA10, $I$14)))<$D$19, IFERROR(P8, IF(O8="", $I$14, O8)), MAX((K35)+$D$16, IFERROR(P8, IF(O8="", $I$14, O8))+($D$13*((($I$14)-IFERROR(sidechannel!AA10, $I$14))))))))) -> 635.5 | Q8: Spill End outlet; lateral spill is capacity-limited and the downstream stage rises when spill capacity is short.
B9: Contraction coeff Kc | C9: - | D9: 0.1 | K9: Inlet-drain | L9: drain | M9: start | N9: Spill Zero | P9: =IF(OR(N9="Known WSE", N9="Known WS"), O9, IF(N9="Known Depth", (J36)+(O9), IF(N9="Normal Depth", (J36)+(MAX($D$16, POWER((ABS(N36)*$D$6)/(MAX(F36, 0.1)*SQRT(MAX(ABS((K36-J36)/MAX(E36, 0.000001)), $D$17))), 3/5))), IF(N9="Critical Depth", (J36)+(MAX($D$16, POWER((ABS(N36)^2)/($I$5*MAX(F36, 0.1)^2), 1/3))), IF(OR(N9="Dead End", N9="None", N9="Spill End"), IF(O9="", (J36)+$D$16, O9), IF(N9="Spill Zero", (J36)+$D$16, (J36)+(MAX($D$16, POWER((ABS(N36)*$D$6)/(MAX(F36, 0.1)*SQRT(MAX(ABS((K36-J36)/MAX(E36, 0.000001)), $D$17))), 3/5))))))))) -> 631.55 | Q9: Master inlet boundary
B10: Bend coeff Kb | C10: - | D10: 0.15 | K10: Outlet-drain | L10: drain | M10: end | N10: Known WSE | O10: 625 | P10: =IF(OR(N10="Known WSE", N10="Known WS"), O10, IF(N10="Known Depth", (K36)+(O10), IF(N10="Normal Depth", (K36)+(MAX($D$16, POWER((ABS(P36)*$D$6)/(MAX(G36, 0.1)*SQRT(MAX(ABS((K36-J36)/MAX(E36, 0.000001)), $D$17))), 3/5))), IF(N10="Critical Depth", (K36)+(MAX($D$16, POWER((ABS(P36)^2)/($I$5*MAX(G36, 0.1)^2), 1/3))), IF(OR(N10="Dead End", N10="None", N10="Spill End"), IF(O10="", (K36)+$D$16, O10), IF(N10="Spill Zero", (K36)+$D$16, (K36)+(MAX($D$16, POWER((ABS(P36)*$D$6)/(MAX(G36, 0.1)*SQRT(MAX(ABS((K36-J36)/MAX(E36, 0.000001)), $D$17))), 3/5))))))))) -> 625 | Q10: Master outlet boundary
B11: Junction coeff base | C11: - | D11: 0.75 | G11: Final alpha J1 | H11: - | I11: =IF($D$20=0, IFERROR($I$11, $D$23), IF(OR(N6="Dead End", N6="None"), MIN(0.98, MAX(0.02, MAX(0, 1-(N33/MAX($D$5, 0.000001))))), MIN(0.98, MAX(0.02, IFERROR($I$11, $D$23)+($D$14*(((IFERROR(UsExit!AI10, IFERROR(UsExit!AA10, $I$13))-IFERROR(waterway!AI10, IFERROR(waterway!AA10, $I$13))))/MAX(ABS($I$13), 1))))))) -> 0.98
B12: Spill coeff Cw | C12: - | D12: 1.7 | G12: Final alpha J2 | H12: - | I12: =IF($D$20=0, IFERROR($I$12, $D$24), IF(AND(OR(N7="Dead End", N7="None"), OR(N8="Dead End", N8="None")), MIN(0.98, MAX(0.02, IFERROR(N34/MAX(N32, 0.000001), IFERROR($I$12, $D$24)))), IF(OR(N8="Dead End", N8="None"), 1, IF(OR(N7="Dead End", N7="None"), 0, MIN(0.98, MAX(0.02, IFERROR($I$12, $D$24)+($D$14*(((IFERROR(sidechannel!AI10, IFERROR(sidechannel!AA10, $I$14))-IFERROR(forebay!AI10, IFERROR(forebay!AA10, $I$14))))/MAX(ABS($I$14), 1))))))))) -> 0.02
B13: Stage relaxation | C13: - | D13: 0.35 | G13: Final J1 WSE | H13: m | I13: =IF($D$20=0, $D$21, IF(ABS($I$16)<$D$19, (IFERROR($I$13, $D$21)), MAX((K31)+$D$16, (IFERROR($I$13, $D$21))+($D$13*$I$16)))) -> 637
B14: Split relaxation | C14: - | D14: 0.08 | G14: Final J2 WSE | H14: m | I14: =IF($D$20=0, $D$22, IF(ABS($I$17)<$D$19, (IFERROR($I$14, $D$22)), MAX((K32)+$D$16, (IFERROR($I$14, $D$22))+($D$13*$I$17)))) -> 644.50593
B15: Junction energy weight | C15: - | D15: 0.05 | G15: Total spill to drain | H15: m3/s | I15: =IFERROR(N36, 0) -> 0.05
B16: Minimum depth | C16: m | D16: 0.05 | G16: J1 junction error | H16: m | I16: =IFERROR($I$18-IFERROR($I$13, $D$21), 0) -> -0.00082745563
B17: Boundary slope | C17: - | D17: 0.001 | G17: J2 junction error | H17: m | I17: =IFERROR($I$19-IFERROR($I$14, $D$22), 0) -> -0.00083851967
B18: Profile relaxation | C18: - | D18: 0.15 | G18: J1 target WSE | H18: m | I18: =IFERROR((IFERROR($I$13, $D$21))+((IF(OR(N6="Dead End", N6="None"), (IFERROR((waterway!AJ10)+IF(OR(N6="Dead End", N6="None"), 0, T32), IFERROR(waterway!AI10, IFERROR(waterway!AA10, $D$21)))), ((ABS(N32)*(IFERROR((waterway!AJ10)+IF(OR(N6="Dead End", N6="None"), 0, T32), IFERROR(waterway!AI10, IFERROR(waterway!AA10, $D$21))))+ABS(N33)*(IFERROR((UsExit!AJ10)+T33, IFERROR(UsExit!AI10, IFERROR(UsExit!AA10, $D$21)))))/MAX(ABS(N32)+ABS(N33), 0.000001))))-(IFERROR(UsProject!AJ21, IFERROR(UsProject!P21, $D$21)))), IFERROR($I$13, $D$21)) -> 636.99917
B19: Profile tolerance | C19: m | D19: 0.001 | G19: J2 target WSE | H19: m | I19: =IFERROR((IFERROR($I$14, $D$22))+((IF((IF(OR(N7="Dead End", N7="None"), 0, ABS(N34)))+(IF(OR(N8="Dead End", N8="None"), 0, ABS(N35)))<=0.000001, (IFERROR(waterway!AJ1396, IFERROR(waterway!P1396, $D$22))), ((IF(OR(N7="Dead End", N7="None"), 0, ABS(N34)))*(IFERROR((forebay!AJ10)+T34, IFERROR(forebay!AI10, IFERROR(forebay!AA10, $D$22))))+(IF(OR(N8="Dead End", N8="None"), 0, ABS(N35)))*(IFERROR((sidechannel!AJ10)+T35, IFERROR(sidechannel!AI10, IFERROR(sidechannel!AA10, $D$22)))))/MAX((IF(OR(N7="Dead End", N7="None"), 0, ABS(N34)))+(IF(OR(N8="Dead End", N8="None"), 0, ABS(N35))), 0.000001)))-(IFERROR(waterway!AJ1396, IFERROR(waterway!P1396, $D$22)))), IFERROR($I$14, $D$22)) -> 644.50509
B20: Reset (0: Hold, 1: Eval) | C20: - | D20: 1 | G20: UsProject done | H20: - | I20: =IFERROR(MIN(UsProject!V10:'UsProject'!V21, UsProject!AG10:'UsProject'!AG21), 0) -> 1
B21: J1 initial WSE | C21: m | D21: 637 | G21: waterway done | H21: - | I21: =IFERROR(MIN(waterway!V10:'waterway'!V1396, waterway!AG10:'waterway'!AG1396), 0) -> 0
B22: J2 initial WSE | C22: m | D22: 636 | G22: UsExit done | H22: - | I22: =IFERROR(MIN(UsExit!V10:'UsExit'!V28, UsExit!AG10:'UsExit'!AG28), 0) -> 0
B23: alpha J1 initial | C23: - | D23: 0.65 | G23: forebay done | H23: - | I23: =IFERROR(MIN(forebay!V10:'forebay'!V48, forebay!AG10:'forebay'!AG48), 0) -> 0
B24: alpha J2 initial | C24: - | D24: 0.65 | G24: sidechannel done | H24: - | I24: =IFERROR(MIN(sidechannel!V10:'sidechannel'!V45, sidechannel!AG10:'sidechannel'!AG45), 0) -> 0
B25: Spill relaxation | C25: - | D25: 0.2 | G25: J1 ready | H25: - | I25: =IFERROR(IF(OR(N6="Dead End", N6="None"), MIN($I$20, $I$21), MIN($I$20, $I$21, $I$22)), 0) -> 0
A26: Junction Internal Boundary Conditions | G26: J2 ready | H26: - | I26: =IFERROR(MIN($I$21, IF(OR(N7="Dead End", N7="None"), 1, $I$23), IF(OR(N8="Dead End", N8="None"), 1, $I$24)), 0) -> 0
A27: Junction WSE cells iterate directly from the reach passes: forward-pass junction stage from the upstream reach and backward-pass junction stages from the connected downstream reaches are compared each recalculation, the junction error is relaxed in small increments, and the updated node stage is fed back into the reach passes.
A30: Segment | B30: From | C30: To | D30: Pts | E30: Length | F30: b_start | G30: b_end | H30: z_start | I30: z_end | J30: bed_start | K30: bed_end | L30: WS_start | M30: WS_end | N30: Q_in | O30: Q_spill | P30: Q_out | Q30: y_avg | R30: Sf_avg | S30: hf | T30: h_junc | U30: h_total | V30: Profile | W30: Start ang | X30: End ang
A31: UsProject | B31: Inlet | C31: Junction1 | D31: 12 | E31: 10.742 | F31: 6.003 | G31: 6.558 | H31: 0 | I31: 0 | J31: 634.32 | K31: 634.298 | L31: =IFERROR(UsProject!AI10, IFERROR(P5, 0)) -> 637 | M31: =IFERROR(UsProject!AI21, IFERROR($I$13, 0)) -> 637 | N31: =$D$5 -> 51 | O31: =IFERROR(_xludf.AGGREGATE(9, 6, UsProject!AO10:'UsProject'!AO21), 0) -> 0 | P31: =MAX(0, IFERROR(UsProject!K21, 0)-IFERROR(UsProject!AO21, 0)-0) -> 51 | Q31: =IFERROR(_xludf.AGGREGATE(1, 6, UsProject!AH10:'UsProject'!AH21), 0) -> 0 | R31: =IFERROR(_xludf.AGGREGATE(1, 6, UsProject!AS10:'UsProject'!AS21), 0) -> 0 | S31: =IFERROR(E31*R31, 0) -> 0 | T31: 0 | U31: =S31+T31 -> 0 | V31: Mixed | W31: -118.025 | X31: -117.982
A32: waterway | B32: Junction1 | C32: Junction2 | D32: 1387 | E32: 1385.515 | F32: 6.558 | G32: 10.206 | H32: 0 | I32: 0 | J32: 634.298 | K32: 631.875 | L32: =IFERROR(waterway!AI10, IFERROR($I$13, 0)) -> 637 | M32: =IFERROR(waterway!AI1396, IFERROR($I$14, 0)) -> 644.50593 | N32: =IF(OR(N6="Dead End", N6="None"), MAX(0, $D$5-N33), $D$5*$I$11) -> 50.95 | O32: =IFERROR(_xludf.AGGREGATE(9, 6, waterway!AO10:'waterway'!AO1396), 0) -> 0 | P32: =MAX(0, IFERROR(waterway!K1396, 0)-IFERROR(waterway!AO1396, 0)-0) -> 50.95 | Q32: =IFERROR(_xludf.AGGREGATE(1, 6, waterway!AH10:'waterway'!AH1396), 0) -> 0 | R32: =IFERROR(_xludf.AGGREGATE(1, 6, waterway!AS10:'waterway'!AS1396), 0) -> 0 | S32: =IFERROR(E32*R32, 0) -> 0 | T32: =IF(OR(N6="Dead End", N6="None"), 0, ($D$11*0.13607488*(ABS(N33)/MAX(ABS($D$5), 0.000001))^2*MAX(((ABS(N32)/MAX(((F32)+(H32)*(MAX($D$16, ($I$13)-(J32))))*(MAX($D$16, ($I$13)-(J32))), 0.000001))^2)/(2*$I$5), ((ABS(N32)/MAX(((G32)+(I32)*(MAX($D$16, ($I$14)-(K32))))*(MAX($D$16, ($I$14)-(K32))), 0.000001))^2)/(2*$I$5)))) -> 0 | U32: =S32+T32 -> 0 | V32: Mixed | W32: -161.275 | X32: -90
A33: UsExit | B33: Junction1 | C33: Outlet | D33: 19 | E33: 17.255 | F33: 6.558 | G33: 5.994 | H33: 0 | I33: 0 | J33: 634.298 | K33: 634.262 | L33: =IFERROR(UsExit!AI10, IFERROR($I$13, 0)) -> 648.79911 | M33: =IFERROR(UsExit!AI28, IFERROR(P6, 0)) -> 648.78436 | N33: =IF(OR(N6="Dead End", N6="None"), MAX(0.05, IFERROR(O33, 0)+0.05), MAX(0, $D$5-N32)) -> 0.05 | O33: =IFERROR(_xludf.AGGREGATE(9, 6, UsExit!AO10:'UsExit'!AO28), 0) -> 0 | P33: 0 | Q33: =IFERROR(_xludf.AGGREGATE(1, 6, UsExit!AH10:'UsExit'!AH28), 0) -> 0 | R33: =IFERROR(_xludf.AGGREGATE(1, 6, UsExit!AS10:'UsExit'!AS28), 0) -> 0 | S33: =IFERROR(E33*R33, 0) -> 0 | T33: =IF(OR(N6="Dead End", N6="None"), 0, ($D$11*0.00000015*(ABS(N32)/MAX(ABS($D$5), 0.000001))^2*MAX(((ABS(N33)/MAX(((F33)+(H33)*(MAX($D$16, ($I$13)-(J33))))*(MAX($D$16, ($I$13)-(J33))), 0.000001))^2)/(2*$I$5), ((ABS(N33)/MAX(((G33)+(I33)*(MAX($D$16, (IF(OR(N6="Dead End", N6="None"), P6, P6))-(K33))))*(MAX($D$16, (IF(OR(N6="Dead End", N6="None"), P6, P6))-(K33))), 0.000001))^2)/(2*$I$5)))) -> 0 | U33: =S33+T33 -> 0 | V33: Mixed | W33: -118.025 | X33: -117.874
A34: forebay | B34: Junction2 | C34: Outlet | D34: 39 | E34: 38 | F34: 10.206 | G34: 5.005 | H34: 0 | I34: 0 | J34: 631.875 | K34: 621.978 | L34: =IFERROR(forebay!AI10, IFERROR($I$14, 0)) -> 644.50593 | M34: =IFERROR(forebay!AI48, IFERROR(P7, 0)) -> 635.5 | N34: =IF(AND(OR(N7="Dead End", N7="None"), OR(N8="Dead End", N8="None")), MAX(0, N32*$I$12), IF(OR(N7="Dead End", N7="None"), MAX(0.05, IFERROR(O34, 0)+0.05), IF(OR(N8="Dead End", N8="None"), MAX(0, N32-N35), N32*$I$12))) -> 1.019 | O34: =IFERROR(_xludf.AGGREGATE(9, 6, forebay!AO10:'forebay'!AO48), 0) -> 0 | P34: 0 | Q34: =IFERROR(_xludf.AGGREGATE(1, 6, forebay!AH10:'forebay'!AH48), 0) -> 0 | R34: =IFERROR(_xludf.AGGREGATE(1, 6, forebay!AS10:'forebay'!AS48), 0) -> 0 | S34: =IFERROR(E34*R34, 0) -> 0 | T34: =IF(OR(OR(N7="Dead End", N7="None"), OR(N8="Dead End", N8="None")), 0, 0) -> 0 | U34: =S34+T34 -> 0 | V34: Mixed | W34: -90 | X34: -90
A35: sidechannel | B35: Junction2 | C35: Outlet | D35: 36 | E35: 34.931 | F35: 10.206 | G35: 3.82 | H35: 0 | I35: 0 | J35: 631.5 | K35: 631.5 | L35: =IFERROR(sidechannel!AI10, IFERROR($I$14, 0)) -> 644.50593 | M35: =IFERROR(sidechannel!AI45, IFERROR(P8, 0)) -> 635.5 | N35: =IF(AND(OR(N7="Dead End", N7="None"), OR(N8="Dead End", N8="None")), MAX(0, N32-N34), IF(OR(N8="Dead End", N8="None"), MAX(0.05, IFERROR(O35, 0)+0.05), IF(OR(N7="Dead End", N7="None"), MAX(0, N32-N34), MAX(0, N32-N34)))) -> 49.931 | O35: =IFERROR(_xludf.AGGREGATE(9, 6, sidechannel!AO10:'sidechannel'!AO45), 0) -> 0 | P35: 0 | Q35: =IFERROR(_xludf.AGGREGATE(1, 6, sidechannel!AH10:'sidechannel'!AH45), 0) -> 0 | R35: =IFERROR(_xludf.AGGREGATE(1, 6, sidechannel!AS10:'sidechannel'!AS45), 0) -> 0 | S35: =IFERROR(E35*R35, 0) -> 0 | T35: =IF(OR(OR(N7="Dead End", N7="None"), OR(N8="Dead End", N8="None")), 0, ($D$11*0.34699541*(ABS(N34)/MAX(ABS(N32), 0.000001))^2*MAX(((ABS(N35)/MAX(((F35)+(H35)*(MAX($D$16, ($I$14)-(J35))))*(MAX($D$16, ($I$14)-(J35))), 0.000001))^2)/(2*$I$5), ((ABS(N35)/MAX(((G35)+(I35)*(MAX($D$16, (P8)-(K35))))*(MAX($D$16, (P8)-(K35))), 0.000001))^2)/(2*$I$5)))) -> 5.6655203e-05 | U35: =S35+T35 -> 5.6655203e-05 | V35: Mixed | W35: -17.819 | X35: -85.755
A36: drain | B36: Inlet | C36: Outlet | D36: 47 | E36: 45.363 | F36: 2.05 | G36: 3.2 | H36: 0 | I36: 0 | J36: 631.5 | K36: 622 | L36: =IFERROR(drain!AI10, IFERROR(P9, 0)) -> 634.5 | M36: =IFERROR(drain!AI56, IFERROR(P10, 0)) -> 625 | N36: =IF(N9="Spill Zero", 0.05, O34+O35) -> 0.05 | O36: 0 | P36: =MAX(0, IFERROR(drain!K56, 0)-IFERROR(drain!AO56, 0)-0.05) -> 0.86561327 | Q36: =IFERROR(_xludf.AGGREGATE(1, 6, drain!AH10:'drain'!AH56), 0) -> 0 | R36: =IFERROR(_xludf.AGGREGATE(1, 6, drain!AS10:'drain'!AS56), 0) -> 0 | S36: =IFERROR(E36*R36, 0) -> 0 | T36: 0 | U36: =S36+T36 -> 0 | V36: Mixed | W36: -65.101 | X36: -90.405

Sheet Sheet1

Sheet UsProject
A1: Reset | B1: Channel | C1: Type | D1: Length | E1: US Condition | F1: US Discharge | G1: US Boundary Condition | H1: Value | I1: DS Condition | J1: DS Discharge | K1: DS Boundary Condition | L1: Value
A2: 1 | B2: ='1D'!A31 -> UsProject | C2: =H10 -> Normal | D2: ='1D'!E31 -> 10.742 | E2: =IF(OR('1D'!B31="Inlet",'1D'!B31="Outlet"),'1D'!B31,"Junction") -> Inlet | F2: ='1D'!N31 -> 51 | G2: ='1D'!N5 -> Known WSE | H2: ='1D'!P5 -> 637 | I2: =IF(OR('1D'!C31="Inlet",'1D'!C31="Outlet"),'1D'!C31,"Junction") -> Junction | J2: ='1D'!P31 -> 51 | K2: Junction | L2: ='1D'!$I$13 -> 637
A4: Water Surface Elevation (WSE) | B4: Initial | C4: Forward Pass | D4: Backward Pass | E4: Final
A5: Upstream | B5: =$H$2 -> 637 | C5: =P10 -> 637 | D5: =AA10 -> 636.95045 | E5: =AI10 -> 637
A6: Downstream | B6: =$L$2 -> 637 | C6: =P21 -> 635.79642 | D6: =AA21 -> 637 | E6: =AI21 -> 637
A8: SN | B8: Dist | C8: Easting | D8: Northing | E8: Bed Z | F8: Width | G8: Side z | H8: Type | I8: Def Ang | J8: dx | K8: Q_used | L8: y_super | M8: A_super | N8: R_super | O8: v_super | P8: WS_super | Q8: EG_super | R8: Sf_super | S8: Fr_super | T8: M_super | U8: Err_super | V8: Done_super | W8: y_sub | X8: A_sub | Y8: R_sub | Z8: v_sub | AA8: WS_sub | AB8: EG_sub | AC8: Sf_sub | AD8: Fr_sub | AE8: M_sub | AF8: Err_sub | AG8: Done_sub | AH8: y_final | AI8: WS_final | AJ8: EG_final | AK8: Crest_L | AL8: Crest_R | AM8: Spill_L | AN8: Spill_R | AO8: Spill_Q | AP8: Cum_spill | AQ8: Fr_final | AR8: Regime | AS8: Sf_final
A9: - | B9: m | C9: m | D9: m | E9: m | F9: m | G9: - | H9: - | I9: deg | J9: m | K9: m3/s | L9: m | M9: m2 | N9: m | O9: m/s | P9: m | Q9: m | R9: - | S9: - | T9: m3 | U9: m | V9: - | W9: m | X9: m2 | Y9: m | Z9: m/s | AA9: m | AB9: m | AC9: - | AD9: - | AE9: m3 | AF9: m | AG9: - | AH9: m | AI9: m | AJ9: m | AK9: m | AL9: m | AM9: m3/s | AN9: m3/s | AO9: m3/s | AP9: m3/s | AQ9: - | AR9: - | AS9: -
A10: 1 | B10: 0 | C10: 616561.06 | D10: 3097769.9 | E10: 634.32 | F10: 6.003 | G10: 0 | H10: Normal | I10: 0 | J10: 0 | K10: =$F$2 -> 51 | L10: =MAX('1D'!$D$16, ($H$2)-E10) -> 2.68 | M10: =((F10)+(G10)*(L10))*(L10) -> 16.08804 | N10: =(((F10)+(G10)*(L10))*(L10))/MAX((F10)+2*(L10)*SQRT(1+(G10)^2), 0.000001) -> 1.4158268 | O10: =ABS(K10)/MAX(((F10)+(G10)*(L10))*(L10), 0.000001) -> 3.1700568 | P10: =E10+L10 -> 637 | Q10: =P10+((ABS(K10)/MAX(((F10)+(G10)*(L10))*(L10), 0.000001))^2)/(2*'1D'!$I$5) -> 637.51219 | R10: =((ABS(K10)*'1D'!$D$6)/(MAX(((F10)+(G10)*(L10))*(L10), 0.000001)*MAX(((((F10)+(G10)*(L10))*(L10))/MAX((F10)+2*(L10)*SQRT(1+(G10)^2), 0.000001))^(2/3), 0.000001)))^2 -> 0.0014222297 | S10: =ABS(ABS(K10)/MAX(((F10)+(G10)*(L10))*(L10), 0.000001))/SQRT('1D'!$I$5*MAX((((F10)+(G10)*(L10))*(L10))/MAX((F10)+2*(G10)*(L10), 0.000001), 0.000001)) -> 0.61825144 | T10: =((F10)*(L10)^2)/2+(G10)*(L10)^3/3+(ABS(K10)^2)/('1D'!$I$5*MAX(((F10)+(G10)*(L10))*(L10), 0.000001)) -> 38.038391 | U10: 0 | V10: 1 | W10: =IF($A$2=0, MAX(MAX('1D'!$D$16, MAX('1D'!$D$16, POWER((ABS(K10)^2)/('1D'!$I$5*MAX(F10, 0.1)^2), 1/3))), IFERROR(W21, MAX(MAX('1D'!$D$16, MAX('1D'!$D$16, POWER((ABS(K10)^2)/('1D'!$I$5*MAX(F10, 0.1)^2), 1/3))), ($L$2)-E21))), IF(IFERROR(AG11, 0)=0, MAX(MAX('1D'!$D$16, MAX('1D'!$D$16, POWER((ABS(K10)^2)/('1D'!$I$5*MAX(F10, 0.1)^2), 1/3))), IFERROR(W21, MAX(MAX('1D'!$D$16, MAX('1D'!$D$16, POWER((ABS(K10)^2)/('1D'!$I$5*MAX(F10, 0.1)^2), 1/3))), ($L$2)-E21))), IF(IFERROR(W10, 0)=0, MAX(MAX('1D'!$D$16, MAX('1D'!$D$16, POWER((ABS(K10)^2)/('1D'!$I$5*MAX(F10, 0.1)^2), 1/3))), IFERROR(W21, MAX(MAX('1D'!$D$16, MAX('1D'!$D$16, POWER((ABS(K10)^2)/('1D'!$I$5*MAX(F10, 0.1)^2), 1/3))), ($L$2)-E21))), IF(OR(IFERROR(AD10, 0)>=1, IFERROR(AD11, 0)>=1), MAX('1D'!$D$16, MAX('1D'!$D$16, POWER((ABS(K10)^2)/('1D'!$I$5*MAX(F10, 0.1)^2), 1/3))), IF(ABS(IFERROR(AF10, 0))<'1D'!$D$19, MAX(MAX('1D'!$D$16, MAX('1D'!$D$16, POWER((ABS(K10)^2)/('1D'!$I$5*MAX(F10, 0.1)^2), 1/3))), IFERROR(W10, 0)), MAX(MAX('1D'!$D$16, MAX('1D'!$D$16, POWER((ABS(K10)^2)/('1D'!$I$5*MAX(F10, 0.1)^2), 1/3))), (IFERROR(W10, 0))+((IFERROR(AF10, 0))*'1D'!$D$18))))))) -> 2.630446 | X10: =((F10)+(G10)*(W10))*(W10) -> 15.790567 | Y10: =(((F10)+(G10)*(W10))*(W10))/MAX((F10)+2*(W10)*SQRT(1+(G10)^2), 0.000001) -> 1.4018749 | Z10: =ABS(K10)/MAX(((F10)+(G10)*(W10))*(W10), 0.000001) -> 3.2297763 | AA10: =E10+W10 -> 636.95045 | AB10: =AA10+((ABS(K10)/MAX(((F10)+(G10)*(W10))*(W10), 0.000001))^2)/(2*'1D'!$I$5) -> 637.48212 | AC10: =((ABS(K10)*'1D'!$D$6)/(MAX(((F10)+(G10)*(W10))*(W10), 0.000001)*MAX(((((F10)+(G10)*(W10))*(W10))/MAX((F10)+2*(W10)*SQRT(1+(G10)^2), 0.000001))^(2/3), 0.000001)))^2 -> 0.0014959431 | AD10: =ABS(ABS(K10)/MAX(((F10)+(G10)*(W10))*(W10), 0.000001))/SQRT('1D'!$I$5*MAX((((F10)+(G10)*(W10))*(W10))/MAX((F10)+2*(G10)*(W10), 0.000001), 0.000001)) -> 0.63580399 | AE10: =((F10)*(W10)^2)/2+(G10)*(W10)^3/3+(ABS(K10)^2)/('1D'!$I$5*MAX(((F10)+(G10)*(W10))*(W10), 0.000001)) -> 37.559003 | AF10: =IF($A$2=0, 0, IFERROR(AB11+(((AC10+AC11)/2)*J11)+(IF(Z10>Z11, '1D'!$D$8*((Z10^2-Z11^2)/(2*'1D'!$I$5)), '1D'!$D$9*((Z11^2-Z10^2)/(2*'1D'!$I$5)))+('1D'!$D$10*(ABS(I11)/90)*(MAX(Z10^2, Z11^2)/(2*'1D'!$I$5))))-AB10, 0)) -> -0.00093480474 | AG10: =IF($A$2=0, 1, IF(IFERROR(AG11, 0)=0, 0, IFERROR(IF(OR(ROUND(AD10, 3)>=1, AND(ABS(AF10)<'1D'!$D$19, AD10<1)), 1, 0), 0))) -> 1 | AH10: =IFERROR(IF('1D'!V31="Supercritical", MAX('1D'!$D$16, IFERROR(L10, MAX('1D'!$D$16, POWER((ABS(K10)^2)/('1D'!$I$5*MAX(F10, 0.1)^2), 1/3)))), IF('1D'!V31="Subcritical", MAX('1D'!$D$16, IFERROR(W10, MAX('1D'!$D$16, POWER((ABS(K10)^2)/('1D'!$I$5*MAX(F10, 0.1)^2), 1/3)))), IF(IFERROR(T10, -1E+99)>=IFERROR(AE10, -1E+99), MAX('1D'!$D$16, IFERROR(L10, MAX('1D'!$D$16, POWER((ABS(K10)^2)/('1D'!$I$5*MAX(F10, 0.1)^2), 1/3)))), MAX('1D'!$D$16, IFERROR(W10, MAX('1D'!$D$16, POWER((ABS(K10)^2)/('1D'!$I$5*MAX(F10, 0.1)^2), 1/3))))))), MAX('1D'!$D$16, POWER((ABS(K10)^2)/('1D'!$I$5*MAX(F10, 0.1)^2), 1/3))) -> 2.68 | AI10: =E10+AH10 -> 637 | AJ10: =AI10+((ABS(K10)/MAX(((F10)+(G10)*(AH10))*(AH10), 0.000001))^2)/(2*'1D'!$I$5) -> 637.51219 | AM10: 0 | AN10: 0 | AO10: =AM10+AN10 -> 0 | AP10: =AO10 -> 0 | AQ10: =ABS(ABS(K10)/MAX(((F10)+(G10)*(AH10))*(AH10), 0.000001))/SQRT('1D'!$I$5*MAX((((F10)+(G10)*(AH10))*(AH10))/MAX((F10)+2*(G10)*(AH10), 0.000001), 0.000001)) -> 0.61825144 | AR10: =IF(AQ10<1, "Subcritical", "Supercritical") -> Subcritical | AS10: =((ABS(K10)*'1D'!$D$6)/(MAX(((F10)+(G10)*(AH10))*(AH10), 0.000001)*MAX(((((F10)+(G10)*(AH10))*(AH10))/MAX((F10)+2*(AH10)*SQRT(1+(G10)^2), 0.000001))^(2/3), 0.000001)))^2 -> 0.0014222297
A11: 2 | B11: 1 | C11: 616560.59 | D11: 3097769 | E11: 634.318 | F11: 6.003 | G11: 0 | H11: Normal | I11: 0 | J11: =B11-B10 -> 1 | K11: =MAX(0, K10-AO10) -> 51 | L11: =IF($A$2=0, IFERROR(L10, MAX('1D'!$D$16, POWER((ABS(K11)^2)/('1D'!$I$5*MAX(F11, 0.1)^2), 1/3))), IF(IFERROR(V10, 0)=0, IFERROR(L10, MAX('1D'!$D$16, POWER((ABS(K11)^2)/('1D'!$I$5*MAX(F11, 0.1)^2), 1/3))), IF(OR(IFERROR(L11, 0)=0, IFERROR(S10, 0)<1, IFERROR(S11, 0)<1), MAX('1D'!$D$16, POWER((ABS(K11)^2)/('1D'!$I$5*MAX(F11, 0.1)^2), 1/3)), IF(IFERROR(U11, 0)>0, MAX('1D'!$D$16, IFERROR(L11, 0)+((IFERROR(U11, 0))*'1D'!$D$18*IF((IFERROR(S11, 0))<1, 1, -1))), IF(IFERROR(U11, 0)<0, IF(ABS((MAX('1D'!$D$16, POWER((ABS(K11)^2)/('1D'!$I$5*MAX(F11, 0.1)^2), 1/3)))-IFERROR(L11, 0))>'1D'!$D$19, MAX('1D'!$D$16, IF((MAX('1D'!$D$16, POWER((ABS(K11)^2)/('1D'!$I$5*MAX(F11, 0.1)^2), 1/3)))>IFERROR(L11, 0), MIN((MAX('1D'!$D$16, POWER((ABS(K11)^2)/('1D'!$I$5*MAX(F11, 0.1)^2), 1/3))), IFERROR(L11, 0)+(MIN(ABS(IFERROR(U11, 0))*'1D'!$D$18, ABS((MAX('1D'!$D$16, POWER((ABS(K11)^2)/('1D'!$I$5*MAX(F11, 0.1)^2), 1/3)))-IFERROR(L11, 0))))), MAX((MAX('1D'!$D$16, POWER((ABS(K11)^2)/('1D'!$I$5*MAX(F11, 0.1)^2), 1/3))), IFERROR(L11, 0)-(MIN(ABS(IFERROR(U11, 0))*'1D'!$D$18, ABS((MAX('1D'!$D$16, POWER((ABS(K11)^2)/('1D'!$I$5*MAX(F11, 0.1)^2), 1/3)))-IFERROR(L11, 0))))))), MAX('1D'!$D$16, POWER((ABS(K11)^2)/('1D'!$I$5*MAX(F11, 0.1)^2), 1/3))), MAX('1D'!$D$16, IFERROR(L11, 0))))))) -> 1.9449639 | M11: =((F11)+(G11)*(L11))*(L11) -> 11.675619 | N11: =(((F11)+(G11)*(L11))*(L11))/MAX((F11)+2*(L11)*SQRT(1+(G11)^2), 0.000001) -> 1.1801985 | O11: =ABS(K11)/MAX(((F11)+(G11)*(L11))*(L11), 0.000001) -> 4.3680769 | P11: =E11+L11 -> 636.26296 | Q11: =P11+((ABS(K11)/MAX(((F11)+(G11)*(L11))*(L11), 0.000001))^2)/(2*'1D'!$I$5) -> 637.23545 | R11: =((ABS(K11)*'1D'!$D$6)/(MAX(((F11)+(G11)*(L11))*(L11), 0.000001)*MAX(((((F11)+(G11)*(L11))*(L11))/MAX((F11)+2*(L11)*SQRT(1+(G11)^2), 0.000001))^(2/3), 0.000001)))^2 -> 0.0034420962 | S11: =ABS(ABS(K11)/MAX(((F11)+(G11)*(L11))*(L11), 0.000001))/SQRT('1D'!$I$5*MAX((((F11)+(G11)*(L11))*(L11))/MAX((F11)+2*(G11)*(L11), 0.000001), 0.000001)) -> 1 | T11: =((F11)*(L11)^2)/2+(G11)*(L11)^3/3+(ABS(K11)^2)/('1D'!$I$5*MAX(((F11)+(G11)*(L11))*(L11), 0.000001)) -> 34.062985 | U11: =IF($A$2=0, 0, IFERROR(Q10-(((R10+R11)/2)*J11)-(IF(O10>O11, '1D'!$D$8*((O10^2-O11^2)/(2*'1D'!$I$5)), '1D'!$D$9*((O11^2-O10^2)/(2*'1D'!$I$5)))+('1D'!$D$10*(ABS(I11)/90)*(MAX(O10^2, O11^2)/(2*'1D'!$I$5))))-Q11, 0)) -> 0.2282879 | V11: =IF($A$2=0, 1, IF(IFERROR(V10, 0)=0, 0, IFERROR(IF(ROUND(S11, 3)=1, 1, IF(AND(ABS(U11)<'1D'!$D$19, S11>1), 1, 0)), 0))) -> 1 | W11: =IF($A$2=0, MAX(MAX('1D'!$D$16, MAX('1D'!$D$16, POWER((ABS(K11)^2)/('1D'!$I$5*MAX(F11, 0.1)^2), 1/3))), IFERROR(W21, MAX(MAX('1D'!$D$16, MAX('1D'!$D$16, POWER((ABS(K11)^2)/('1D'!$I$5*MAX(F11, 0.1)^2), 1/3))), ($L$2)-E21))), IF(IFERROR(AG12, 0)=0, MAX(MAX('1D'!$D$16, MAX('1D'!$D$16, POWER((ABS(K11)^2)/('1D'!$I$5*MAX(F11, 0.1)^2), 1/3))), IFERROR(W21, MAX(MAX('1D'!$D$16, MAX('1D'!$D$16, POWER((ABS(K11)^2)/('1D'!$I$5*MAX(F11, 0.1)^2), 1/3))), ($L$2)-E21))), IF(IFERROR(W11, 0)=0, MAX(MAX('1D'!$D$16, MAX('1D'!$D$16, POWER((ABS(K11)^2)/('1D'!$I$5*MAX(F11, 0.1)^2), 1/3))), IFERROR(W21, MAX(MAX('1D'!$D$16, MAX('1D'!$D$16, POWER((ABS(K11)^2)/('1D'!$I$5*MAX(F11, 0.1)^2), 1/3))), ($L$2)-E21))), IF(OR(IFERROR(AD11, 0)>=1, IFERROR(AD12, 0)>=1), MAX('1D'!$D$16, MAX('1D'!$D$16, POWER((ABS(K11)^2)/('1D'!$I$5*MAX(F11, 0.1)^2), 1/3))), IF(ABS(IFERROR(AF11, 0))<'1D'!$D$19, MAX(MAX('1D'!$D$16, MAX('1D'!$D$16, POWER((ABS(K11)^2)/('1D'!$I$5*MAX(F11, 0.1)^2), 1/3))), IFERROR(W11, 0)), MAX(MAX('1D'!$D$16, MAX('1D'!$D$16, POWER((ABS(K11)^2)/('1D'!$I$5*MAX(F11, 0.1)^2), 1/3))), (IFERROR(W11, 0))+((IFERROR(AF11, 0))*'1D'!$D$18))))))) -> 2.629669 | X11: =((F11)+(G11)*(W11))*(W11) -> 15.785903 | Y11: =(((F11)+(G11)*(W11))*(W11))/MAX((F11)+2*(W11)*SQRT(1+(G11)^2), 0.000001) -> 1.4016542 | Z11: =ABS(K11)/MAX(((F11)+(G11)*(W11))*(W11), 0.000001) -> 3.2307307 | AA11: =E11+W11 -> 636.94767 | AB11: =AA11+((ABS(K11)/MAX(((F11)+(G11)*(W11))*(W11), 0.000001))^2)/(2*'1D'!$I$5) -> 637.47966 | AC11: =((ABS(K11)*'1D'!$D$6)/(MAX(((F11)+(G11)*(W11))*(W11), 0.000001)*MAX(((((F11)+(G11)*(W11))*(W11))/MAX((F11)+2*(W11)*SQRT(1+(G11)^2), 0.000001))^(2/3), 0.000001)))^2 -> 0.0014971416 | AD11: =ABS(ABS(K11)/MAX(((F11)+(G11)*(W11))*(W11), 0.000001))/SQRT('1D'!$I$5*MAX((((F11)+(G11)*(W11))*(W11))/MAX((F11)+2*(G11)*(W11), 0.000001), 0.000001)) -> 0.63608581 | AE11: =((F11)*(W11)^2)/2+(G11)*(W11)^3/3+(ABS(K11)^2)/('1D'!$I$5*MAX(((F11)+(G11)*(W11))*(W11), 0.000001)) -> 37.551697 | AF11: =IF($A$2=0, 0, IFERROR(AB12+(((AC11+AC12)/2)*J12)+(IF(Z11>Z12, '1D'!$D$8*((Z11^2-Z12^2)/(2*'1D'!$I$5)), '1D'!$D$9*((Z12^2-Z11^2)/(2*'1D'!$I$5)))+('1D'!$D$10*(ABS(I12)/90)*(MAX(Z11^2, Z12^2)/(2*'1D'!$I$5))))-AB11, 0)) -> -0.00094662428 | AG11: =IF($A$2=0, 1, IF(IFERROR(AG12, 0)=0, 0, IFERROR(IF(OR(ROUND(AD11, 3)>=1, AND(ABS(AF11)<'1D'!$D$19, AD11<1)), 1, 0), 0))) -> 1 | AH11: =IFERROR(IF('1D'!V31="Supercritical", MAX('1D'!$D$16, IFERROR(L11, MAX('1D'!$D$16, POWER((ABS(K11)^2)/('1D'!$I$5*MAX(F11, 0.1)^2), 1/3)))), IF('1D'!V31="Subcritical", MAX('1D'!$D$16, IFERROR(W11, MAX('1D'!$D$16, POWER((ABS(K11)^2)/('1D'!$I$5*MAX(F11, 0.1)^2), 1/3)))), IF(IFERROR(T11, -1E+99)>=IFERROR(AE11, -1E+99), MAX('1D'!$D$16, IFERROR(L11, MAX('1D'!$D$16, POWER((ABS(K11)^2)/('1D'!$I$5*MAX(F11, 0.1)^2), 1/3)))), MAX('1D'!$D$16, IFERROR(W11, MAX('1D'!$D$16, POWER((ABS(K11)^2)/('1D'!$I$5*MAX(F11, 0.1)^2), 1/3))))))), MAX('1D'!$D$16, POWER((ABS(K11)^2)/('1D'!$I$5*MAX(F11, 0.1)^2), 1/3))) -> 2.629669 | AI11: =E11+AH11 -> 636.94767 | AJ11: =AI11+((ABS(K11)/MAX(((F11)+(G11)*(AH11))*(AH11), 0.000001))^2)/(2*'1D'!$I$5) -> 637.47966 | AM11: 0 | AN11: 0 | AO11: =AM11+AN11 -> 0 | AP11: =AP10+AO11 -> 0 | AQ11: =ABS(ABS(K11)/MAX(((F11)+(G11)*(AH11))*(AH11), 0.000001))/SQRT('1D'!$I$5*MAX((((F11)+(G11)*(AH11))*(AH11))/MAX((F11)+2*(G11)*(AH11), 0.000001), 0.000001)) -> 0.63608581 | AR11: =IF(AQ11<1, "Subcritical", "Supercritical") -> Subcritical | AS11: =((ABS(K11)*'1D'!$D$6)/(MAX(((F11)+(G11)*(AH11))*(AH11), 0.000001)*MAX(((((F11)+(G11)*(AH11))*(AH11))/MAX((F11)+2*(AH11)*SQRT(1+(G11)^2), 0.000001))^(2/3), 0.000001)))^2 -> 0.0014971416
A12: 3 | B12: 2.001 | C12: 616560.12 | D12: 3097768.2 | E12: 634.316 | F12: 6.004 | G12: 0 | H12: Normal | I12: 0.027 | J12: =B12-B11 -> 1.001 | K12: =MAX(0, K11-AO11) -> 51 | L12: =IF($A$2=0, IFERROR(L11, MAX('1D'!$D$16, POWER((ABS(K12)^2)/('1D'!$I$5*MAX(F12, 0.1)^2), 1/3))), IF(IFERROR(V11, 0)=0, IFERROR(L11, MAX('1D'!$D$16, POWER((ABS(K12)^2)/('1D'!$I$5*MAX(F12, 0.1)^2), 1/3))), IF(OR(IFERROR(L12, 0)=0, IFERROR(S11, 0)<1, IFERROR(S12, 0)<1), MAX('1D'!$D$16, POWER((ABS(K12)^2)/('1D'!$I$5*MAX(F12, 0.1)^2), 1/3)), IF(IFERROR(U12, 0)>0, MAX('1D'!$D$16, IFERROR(L12, 0)+((IFERROR(U12, 0))*'1D'!$D$18*IF((IFERROR(S12, 0))<1, 1, -1))), IF(IFERROR(U12, 0)<0, IF(ABS((MAX('1D'!$D$16, POWER((ABS(K12)^2)/('1D'!$I$5*MAX(F12, 0.1)^2), 1/3)))-IFERROR(L12, 0))>'1D'!$D$19, MAX('1D'!$D$16, IF((MAX('1D'!$D$16, POWER((ABS(K12)^2)/('1D'!$I$5*MAX(F12, 0.1)^2), 1/3)))>IFERROR(L12, 0), MIN((MAX('1D'!$D$16, POWER((ABS(K12)^2)/('1D'!$I$5*MAX(F12, 0.1)^2), 1/3))), IFERROR(L12, 0)+(MIN(ABS(IFERROR(U12, 0))*'1D'!$D$18, ABS((MAX('1D'!$D$16, POWER((ABS(K12)^2)/('1D'!$I$5*MAX(F12, 0.1)^2), 1/3)))-IFERROR(L12, 0))))), MAX((MAX('1D'!$D$16, POWER((ABS(K12)^2)/('1D'!$I$5*MAX(F12, 0.1)^2), 1/3))), IFERROR(L12, 0)-(MIN(ABS(IFERROR(U12, 0))*'1D'!$D$18, ABS((MAX('1D'!$D$16, POWER((ABS(K12)^2)/('1D'!$I$5*MAX(F12, 0.1)^2), 1/3)))-IFERROR(L12, 0))))))), MAX('1D'!$D$16, POWER((ABS(K12)^2)/('1D'!$I$5*MAX(F12, 0.1)^2), 1/3))), MAX('1D'!$D$16, IFERROR(L12, 0))))))) -> 1.944748 | M12: =((F12)+(G12)*(L12))*(L12) -> 11.676267 | N12: =(((F12)+(G12)*(L12))*(L12))/MAX((F12)+2*(L12)*SQRT(1+(G12)^2), 0.000001) -> 1.1801962 | O12: =ABS(K12)/MAX(((F12)+(G12)*(L12))*(L12), 0.000001) -> 4.3678344 | P12: =E12+L12 -> 636.26075 | Q12: =P12+((ABS(K12)/MAX(((F12)+(G12)*(L12))*(L12), 0.000001))^2)/(2*'1D'!$I$5) -> 637.23312 | R12: =((ABS(K12)*'1D'!$D$6)/(MAX(((F12)+(G12)*(L12))*(L12), 0.000001)*MAX(((((F12)+(G12)*(L12))*(L12))/MAX((F12)+2*(L12)*SQRT(1+(G12)^2), 0.000001))^(2/3), 0.000001)))^2 -> 0.0034417227 | S12: =ABS(ABS(K12)/MAX(((F12)+(G12)*(L12))*(L12), 0.000001))/SQRT('1D'!$I$5*MAX((((F12)+(G12)*(L12))*(L12))/MAX((F12)+2*(G12)*(L12), 0.000001), 0.000001)) -> 1 | T12: =((F12)*(L12)^2)/2+(G12)*(L12)^3/3+(ABS(K12)^2)/('1D'!$I$5*MAX(((F12)+(G12)*(L12))*(L12), 0.000001)) -> 34.061094 | U12: =IF($A$2=0, 0, IFERROR(Q11-(((R11+R12)/2)*J12)-(IF(O11>O12, '1D'!$D$8*((O11^2-O12^2)/(2*'1D'!$I$5)), '1D'!$D$9*((O12^2-O11^2)/(2*'1D'!$I$5)))+('1D'!$D$10*(ABS(I12)/90)*(MAX(O11^2, O12^2)/(2*'1D'!$I$5))))-Q12, 0)) -> -0.0011975548 | V12: =IF($A$2=0, 1, IF(IFERROR(V11, 0)=0, 0, IFERROR(IF(ROUND(S12, 3)=1, 1, IF(AND(ABS(U12)<'1D'!$D$19, S12>1), 1, 0)), 0))) -> 1 | W12: =IF($A$2=0, MAX(MAX('1D'!$D$16, MAX('1D'!$D$16, POWER((ABS(K12)^2)/('1D'!$I$5*MAX(F12, 0.1)^2), 1/3))), IFERROR(W21, MAX(MAX('1D'!$D$16, MAX('1D'!$D$16, POWER((ABS(K12)^2)/('1D'!$I$5*MAX(F12, 0.1)^2), 1/3))), ($L$2)-E21))), IF(IFERROR(AG13, 0)=0, MAX(MAX('1D'!$D$16, MAX('1D'!$D$16, POWER((ABS(K12)^2)/('1D'!$I$5*MAX(F12, 0.1)^2), 1/3))), IFERROR(W21, MAX(MAX('1D'!$D$16, MAX('1D'!$D$16, POWER((ABS(K12)^2)/('1D'!$I$5*MAX(F12, 0.1)^2), 1/3))), ($L$2)-E21))), IF(IFERROR(W12, 0)=0, MAX(MAX('1D'!$D$16, MAX('1D'!$D$16, POWER((ABS(K12)^2)/('1D'!$I$5*MAX(F12, 0.1)^2), 1/3))), IFERROR(W21, MAX(MAX('1D'!$D$16, MAX('1D'!$D$16, POWER((ABS(K12)^2)/('1D'!$I$5*MAX(F12, 0.1)^2), 1/3))), ($L$2)-E21))), IF(OR(IFERROR(AD12, 0)>=1, IFERROR(AD13, 0)>=1), MAX('1D'!$D$16, MAX('1D'!$D$16, POWER((ABS(K12)^2)/('1D'!$I$5*MAX(F12, 0.1)^2), 1/3))), IF(ABS(IFERROR(AF12, 0))<'1D'!$D$19, MAX(MAX('1D'!$D$16, MAX('1D'!$D$16, POWER((ABS(K12)^2)/('1D'!$I$5*MAX(F12, 0.1)^2), 1/3))), IFERROR(W12, 0)), MAX(MAX('1D'!$D$16, MAX('1D'!$D$16, POWER((ABS(K12)^2)/('1D'!$I$5*MAX(F12, 0.1)^2), 1/3))), (IFERROR(W12, 0))+((IFERROR(AF12, 0))*'1D'!$D$18))))))) -> 2.6291746 | X12: =((F12)+(G12)*(W12))*(W12) -> 15.785564 | Y12: =(((F12)+(G12)*(W12))*(W12))/MAX((F12)+2*(W12)*SQRT(1+(G12)^2), 0.000001) -> 1.4016227 | Z12: =ABS(K12)/MAX(((F12)+(G12)*(W12))*(W12), 0.000001) -> 3.2307999 | AA12: =E12+W12 -> 636.94517 | AB12: =AA12+((ABS(K12)/MAX(((F12)+(G12)*(W12))*(W12), 0.000001))^2)/(2*'1D'!$I$5) -> 637.47719 | AC12: =((ABS(K12)*'1D'!$D$6)/(MAX(((F12)+(G12)*(W12))*(W12), 0.000001)*MAX(((((F12)+(G12)*(W12))*(W12))/MAX((F12)+2*(W12)*SQRT(1+(G12)^2), 0.000001))^(2/3), 0.000001)))^2 -> 0.0014972505 | AD12: =ABS(ABS(K12)/MAX(((F12)+(G12)*(W12))*(W12), 0.000001))/SQRT('1D'!$I$5*MAX((((F12)+(G12)*(W12))*(W12))/MAX((F12)+2*(G12)*(W12), 0.000001), 0.000001)) -> 0.63615925 | AE12: =((F12)*(W12)^2)/2+(G12)*(W12)^3/3+(ABS(K12)^2)/('1D'!$I$5*MAX(((F12)+(G12)*(W12))*(W12), 0.000001)) -> 37.54771 | AF12: =IF($A$2=0, 0, IFERROR(AB13+(((AC12+AC13)/2)*J13)+(IF(Z12>Z13, '1D'!$D$8*((Z12^2-Z13^2)/(2*'1D'!$I$5)), '1D'!$D$9*((Z13^2-Z12^2)/(2*'1D'!$I$5)))+('1D'!$D$10*(ABS(I13)/90)*(MAX(Z12^2, Z13^2)/(2*'1D'!$I$5))))-AB12, 0)) -> -0.00095342657 | AG12: =IF($A$2=0, 1, IF(IFERROR(AG13, 0)=0, 0, IFERROR(IF(OR(ROUND(AD12, 3)>=1, AND(ABS(AF12)<'1D'!$D$19, AD12<1)), 1, 0), 0))) -> 1 | AH12: =IFERROR(IF('1D'!V31="Supercritical", MAX('1D'!$D$16, IFERROR(L12, MAX('1D'!$D$16, POWER((ABS(K12)^2)/('1D'!$I$5*MAX(F12, 0.1)^2), 1/3)))), IF('1D'!V31="Subcritical", MAX('1D'!$D$16, IFERROR(W12, MAX('1D'!$D$16, POWER((ABS(K12)^2)/('1D'!$I$5*MAX(F12, 0.1)^2), 1/3)))), IF(IFERROR(T12, -1E+99)>=IFERROR(AE12, -1E+99), MAX('1D'!$D$16, IFERROR(L12, MAX('1D'!$D$16, POWER((ABS(K12)^2)/('1D'!$I$5*MAX(F12, 0.1)^2), 1/3)))), MAX('1D'!$D$16, IFERROR(W12, MAX('1D'!$D$16, POWER((ABS(K12)^2)/('1D'!$I$5*MAX(F12, 0.1)^2), 1/3))))))), MAX('1D'!$D$16, POWER((ABS(K12)^2)/('1D'!$I$5*MAX(F12, 0.1)^2), 1/3))) -> 2.6291746 | AI12: =E12+AH12 -> 636.94517 | AJ12: =AI12+((ABS(K12)/MAX(((F12)+(G12)*(AH12))*(AH12), 0.000001))^2)/(2*'1D'!$I$5) -> 637.47719 | AM12: 0 | AN12: 0 | AO12: =AM12+AN12 -> 0 | AP12: =AP11+AO12 -> 0 | AQ12: =ABS(ABS(K12)/MAX(((F12)+(G12)*(AH12))*(AH12), 0.000001))/SQRT('1D'!$I$5*MAX((((F12)+(G12)*(AH12))*(AH12))/MAX((F12)+2*(G12)*(AH12), 0.000001), 0.000001)) -> 0.63615925 | AR12: =IF(AQ12<1, "Subcritical", "Supercritical") -> Subcritical | AS12: =((ABS(K12)*'1D'!$D$6)/(MAX(((F12)+(G12)*(AH12))*(AH12), 0.000001)*MAX(((((F12)+(G12)*(AH12))*(AH12))/MAX((F12)+2*(AH12)*SQRT(1+(G12)^2), 0.000001))^(2/3), 0.000001)))^2 -> 0.0014972505
A13: 4 | B13: 3 | C13: 616559.65 | D13: 3097767.3 | E13: 634.314 | F13: 6.004 | G13: 0 | H13: Normal | I13: 0.027 | J13: =B13-B12 -> 0.999 | K13: =MAX(0, K12-AO12) -> 51 | L13: =IF($A$2=0, IFERROR(L12, MAX('1D'!$D$16, POWER((ABS(K13)^2)/('1D'!$I$5*MAX(F13, 0.1)^2), 1/3))), IF(IFERROR(V12, 0)=0, IFERROR(L12, MAX('1D'!$D$16, POWER((ABS(K13)^2)/('1D'!$I$5*MAX(F13, 0.1)^2), 1/3))), IF(OR(IFERROR(L13, 0)=0, IFERROR(S12, 0)<1, IFERROR(S13, 0)<1), MAX('1D'!$D$16, POWER((ABS(K13)^2)/('1D'!$I$5*MAX(F13, 0.1)^2), 1/3)), IF(IFERROR(U13, 0)>0, MAX('1D'!$D$16, IFERROR(L13, 0)+((IFERROR(U13, 0))*'1D'!$D$18*IF((IFERROR(S13, 0))<1, 1, -1))), IF(IFERROR(U13, 0)<0, IF(ABS((MAX('1D'!$D$16, POWER((ABS(K13)^2)/('1D'!$I$5*MAX(F13, 0.1)^2), 1/3)))-IFERROR(L13, 0))>'1D'!$D$19, MAX('1D'!$D$16, IF((MAX('1D'!$D$16, POWER((ABS(K13)^2)/('1D'!$I$5*MAX(F13, 0.1)^2), 1/3)))>IFERROR(L13, 0), MIN((MAX('1D'!$D$16, POWER((ABS(K13)^2)/('1D'!$I$5*MAX(F13, 0.1)^2), 1/3))), IFERROR(L13, 0)+(MIN(ABS(IFERROR(U13, 0))*'1D'!$D$18, ABS((MAX('1D'!$D$16, POWER((ABS(K13)^2)/('1D'!$I$5*MAX(F13, 0.1)^2), 1/3)))-IFERROR(L13, 0))))), MAX((MAX('1D'!$D$16, POWER((ABS(K13)^2)/('1D'!$I$5*MAX(F13, 0.1)^2), 1/3))), IFERROR(L13, 0)-(MIN(ABS(IFERROR(U13, 0))*'1D'!$D$18, ABS((MAX('1D'!$D$16, POWER((ABS(K13)^2)/('1D'!$I$5*MAX(F13, 0.1)^2), 1/3)))-IFERROR(L13, 0))))))), MAX('1D'!$D$16, POWER((ABS(K13)^2)/('1D'!$I$5*MAX(F13, 0.1)^2), 1/3))), MAX('1D'!$D$16, IFERROR(L13, 0))))))) -> 1.944748 | M13: =((F13)+(G13)*(L13))*(L13) -> 11.676267 | N13: =(((F13)+(G13)*(L13))*(L13))/MAX((F13)+2*(L13)*SQRT(1+(G13)^2), 0.000001) -> 1.1801962 | O13: =ABS(K13)/MAX(((F13)+(G13)*(L13))*(L13), 0.000001) -> 4.3678344 | P13: =E13+L13 -> 636.25875 | Q13: =P13+((ABS(K13)/MAX(((F13)+(G13)*(L13))*(L13), 0.000001))^2)/(2*'1D'!$I$5) -> 637.23112 | R13: =((ABS(K13)*'1D'!$D$6)/(MAX(((F13)+(G13)*(L13))*(L13), 0.000001)*MAX(((((F13)+(G13)*(L13))*(L13))/MAX((F13)+2*(L13)*SQRT(1+(G13)^2), 0.000001))^(2/3), 0.000001)))^2 -> 0.0034417227 | S13: =ABS(ABS(K13)/MAX(((F13)+(G13)*(L13))*(L13), 0.000001))/SQRT('1D'!$I$5*MAX((((F13)+(G13)*(L13))*(L13))/MAX((F13)+2*(G13)*(L13), 0.000001), 0.000001)) -> 1 | T13: =((F13)*(L13)^2)/2+(G13)*(L13)^3/3+(ABS(K13)^2)/('1D'!$I$5*MAX(((F13)+(G13)*(L13))*(L13), 0.000001)) -> 34.061094 | U13: =IF($A$2=0, 0, IFERROR(Q12-(((R12+R13)/2)*J13)-(IF(O12>O13, '1D'!$D$8*((O12^2-O13^2)/(2*'1D'!$I$5)), '1D'!$D$9*((O13^2-O12^2)/(2*'1D'!$I$5)))+('1D'!$D$10*(ABS(I13)/90)*(MAX(O12^2, O13^2)/(2*'1D'!$I$5))))-Q13, 0)) -> -0.0014820378 | V13: =IF($A$2=0, 1, IF(IFERROR(V12, 0)=0, 0, IFERROR(IF(ROUND(S13, 3)=1, 1, IF(AND(ABS(U13)<'1D'!$D$19, S13>1), 1, 0)), 0))) -> 1 | W13: =IF($A$2=0, MAX(MAX('1D'!$D$16, MAX('1D'!$D$16, POWER((ABS(K13)^2)/('1D'!$I$5*MAX(F13, 0.1)^2), 1/3))), IFERROR(W21, MAX(MAX('1D'!$D$16, MAX('1D'!$D$16, POWER((ABS(K13)^2)/('1D'!$I$5*MAX(F13, 0.1)^2), 1/3))), ($L$2)-E21))), IF(IFERROR(AG14, 0)=0, MAX(MAX('1D'!$D$16, MAX('1D'!$D$16, POWER((ABS(K13)^2)/('1D'!$I$5*MAX(F13, 0.1)^2), 1/3))), IFERROR(W21, MAX(MAX('1D'!$D$16, MAX('1D'!$D$16, POWER((ABS(K13)^2)/('1D'!$I$5*MAX(F13, 0.1)^2), 1/3))), ($L$2)-E21))), IF(IFERROR(W13, 0)=0, MAX(MAX('1D'!$D$16, MAX('1D'!$D$16, POWER((ABS(K13)^2)/('1D'!$I$5*MAX(F13, 0.1)^2), 1/3))), IFERROR(W21, MAX(MAX('1D'!$D$16, MAX('1D'!$D$16, POWER((ABS(K13)^2)/('1D'!$I$5*MAX(F13, 0.1)^2), 1/3))), ($L$2)-E21))), IF(OR(IFERROR(AD13, 0)>=1, IFERROR(AD14, 0)>=1), MAX('1D'!$D$16, MAX('1D'!$D$16, POWER((ABS(K13)^2)/('1D'!$I$5*MAX(F13, 0.1)^2), 1/3))), IF(ABS(IFERROR(AF13, 0))<'1D'!$D$19, MAX(MAX('1D'!$D$16, MAX('1D'!$D$16, POWER((ABS(K13)^2)/('1D'!$I$5*MAX(F13, 0.1)^2), 1/3))), IFERROR(W13, 0)), MAX(MAX('1D'!$D$16, MAX('1D'!$D$16, POWER((ABS(K13)^2)/('1D'!$I$5*MAX(F13, 0.1)^2), 1/3))), (IFERROR(W13, 0))+((IFERROR(AF13, 0))*'1D'!$D$18))))))) -> 2.6283203 | X13: =((F13)+(G13)*(W13))*(W13) -> 15.780435 | Y13: =(((F13)+(G13)*(W13))*(W13))/MAX((F13)+2*(W13)*SQRT(1+(G13)^2), 0.000001) -> 1.4013799 | Z13: =ABS(K13)/MAX(((F13)+(G13)*(W13))*(W13), 0.000001) -> 3.23185 | AA13: =E13+W13 -> 636.94232 | AB13: =AA13+((ABS(K13)/MAX(((F13)+(G13)*(W13))*(W13), 0.000001))^2)/(2*'1D'!$I$5) -> 637.47468 | AC13: =((ABS(K13)*'1D'!$D$6)/(MAX(((F13)+(G13)*(W13))*(W13), 0.000001)*MAX(((((F13)+(G13)*(W13))*(W13))/MAX((F13)+2*(W13)*SQRT(1+(G13)^2), 0.000001))^(2/3), 0.000001)))^2 -> 0.0014985701 | AD13: =ABS(ABS(K13)/MAX(((F13)+(G13)*(W13))*(W13), 0.000001))/SQRT('1D'!$I$5*MAX((((F13)+(G13)*(W13))*(W13))/MAX((F13)+2*(G13)*(W13), 0.000001), 0.000001)) -> 0.63646943 | AE13: =((F13)*(W13)^2)/2+(G13)*(W13)^3/3+(ABS(K13)^2)/('1D'!$I$5*MAX(((F13)+(G13)*(W13))*(W13), 0.000001)) -> 37.539686 | AF13: =IF($A$2=0, 0, IFERROR(AB14+(((AC13+AC14)/2)*J14)+(IF(Z13>Z14, '1D'!$D$8*((Z13^2-Z14^2)/(2*'1D'!$I$5)), '1D'!$D$9*((Z14^2-Z13^2)/(2*'1D'!$I$5)))+('1D'!$D$10*(ABS(I14)/90)*(MAX(Z13^2, Z14^2)/(2*'1D'!$I$5))))-AB13, 0)) -> -0.00096648535 | AG13: =IF($A$2=0, 1, IF(IFERROR(AG14, 0)=0, 0, IFERROR(IF(OR(ROUND(AD13, 3)>=1, AND(ABS(AF13)<'1D'!$D$19, AD13<1)), 1, 0), 0))) -> 1 | AH13: =IFERROR(IF('1D'!V31="Supercritical", MAX('1D'!$D$16, IFERROR(L13, MAX('1D'!$D$16, POWER((ABS(K13)^2)/('1D'!$I$5*MAX(F13, 0.1)^2), 1/3)))), IF('1D'!V31="Subcritical", MAX('1D'!$D$16, IFERROR(W13, MAX('1D'!$D$16, POWER((ABS(K13)^2)/('1D'!$I$5*MAX(F13, 0.1)^2), 1/3)))), IF(IFERROR(T13, -1E+99)>=IFERROR(AE13, -1E+99), MAX('1D'!$D$16, IFERROR(L13, MAX('1D'!$D$16, POWER((ABS(K13)^2)/('1D'!$I$5*MAX(F13, 0.1)^2), 1/3)))), MAX('1D'!$D$16, IFERROR(W13, MAX('1D'!$D$16, POWER((ABS(K13)^2)/('1D'!$I$5*MAX(F13, 0.1)^2), 1/3))))))), MAX('1D'!$D$16, POWER((ABS(K13)^2)/('1D'!$I$5*MAX(F13, 0.1)^2), 1/3))) -> 2.6283203 | AI13: =E13+AH13 -> 636.94232 | AJ13: =AI13+((ABS(K13)/MAX(((F13)+(G13)*(AH13))*(AH13), 0.000001))^2)/(2*'1D'!$I$5) -> 637.47468 | AM13: 0 | AN13: 0 | AO13: =AM13+AN13 -> 0 | AP13: =AP12+AO13 -> 0 | AQ13: =ABS(ABS(K13)/MAX(((F13)+(G13)*(AH13))*(AH13), 0.000001))/SQRT('1D'!$I$5*MAX((((F13)+(G13)*(AH13))*(AH13))/MAX((F13)+2*(G13)*(AH13), 0.000001), 0.000001)) -> 0.63646943 | AR13: =IF(AQ13<1, "Subcritical", "Supercritical") -> Subcritical | AS13: =((ABS(K13)*'1D'!$D$6)/(MAX(((F13)+(G13)*(AH13))*(AH13), 0.000001)*MAX(((((F13)+(G13)*(AH13))*(AH13))/MAX((F13)+2*(AH13)*SQRT(1+(G13)^2), 0.000001))^(2/3), 0.000001)))^2 -> 0.0014985701
A14: 5 | B14: 4 | C14: 616559.18 | D14: 3097766.4 | E14: 634.312 | F14: 6.005 | G14: 0 | H14: Normal | I14: 0 | J14: =B14-B13 -> 1 | K14: =MAX(0, K13-AO13) -> 51 | L14: =IF($A$2=0, IFERROR(L13, MAX('1D'!$D$16, POWER((ABS(K14)^2)/('1D'!$I$5*MAX(F14, 0.1)^2), 1/3))), IF(IFERROR(V13, 0)=0, IFERROR(L13, MAX('1D'!$D$16, POWER((ABS(K14)^2)/('1D'!$I$5*MAX(F14, 0.1)^2), 1/3))), IF(OR(IFERROR(L14, 0)=0, IFERROR(S13, 0)<1, IFERROR(S14, 0)<1), MAX('1D'!$D$16, POWER((ABS(K14)^2)/('1D'!$I$5*MAX(F14, 0.1)^2), 1/3)), IF(IFERROR(U14, 0)>0, MAX('1D'!$D$16, IFERROR(L14, 0)+((IFERROR(U14, 0))*'1D'!$D$18*IF((IFERROR(S14, 0))<1, 1, -1))), IF(IFERROR(U14, 0)<0, IF(ABS((MAX('1D'!$D$16, POWER((ABS(K14)^2)/('1D'!$I$5*MAX(F14, 0.1)^2), 1/3)))-IFERROR(L14, 0))>'1D'!$D$19, MAX('1D'!$D$16, IF((MAX('1D'!$D$16, POWER((ABS(K14)^2)/('1D'!$I$5*MAX(F14, 0.1)^2), 1/3)))>IFERROR(L14, 0), MIN((MAX('1D'!$D$16, POWER((ABS(K14)^2)/('1D'!$I$5*MAX(F14, 0.1)^2), 1/3))), IFERROR(L14, 0)+(MIN(ABS(IFERROR(U14, 0))*'1D'!$D$18, ABS((MAX('1D'!$D$16, POWER((ABS(K14)^2)/('1D'!$I$5*MAX(F14, 0.1)^2), 1/3)))-IFERROR(L14, 0))))), MAX((MAX('1D'!$D$16, POWER((ABS(K14)^2)/('1D'!$I$5*MAX(F14, 0.1)^2), 1/3))), IFERROR(L14, 0)-(MIN(ABS(IFERROR(U14, 0))*'1D'!$D$18, ABS((MAX('1D'!$D$16, POWER((ABS(K14)^2)/('1D'!$I$5*MAX(F14, 0.1)^2), 1/3)))-IFERROR(L14, 0))))))), MAX('1D'!$D$16, POWER((ABS(K14)^2)/('1D'!$I$5*MAX(F14, 0.1)^2), 1/3))), MAX('1D'!$D$16, IFERROR(L14, 0))))))) -> 1.9445321 | M14: =((F14)+(G14)*(L14))*(L14) -> 11.676915 | N14: =(((F14)+(G14)*(L14))*(L14))/MAX((F14)+2*(L14)*SQRT(1+(G14)^2), 0.000001) -> 1.180194 | O14: =ABS(K14)/MAX(((F14)+(G14)*(L14))*(L14), 0.000001) -> 4.367592 | P14: =E14+L14 -> 636.25653 | Q14: =P14+((ABS(K14)/MAX(((F14)+(G14)*(L14))*(L14), 0.000001))^2)/(2*'1D'!$I$5) -> 637.2288 | R14: =((ABS(K14)*'1D'!$D$6)/(MAX(((F14)+(G14)*(L14))*(L14), 0.000001)*MAX(((((F14)+(G14)*(L14))*(L14))/MAX((F14)+2*(L14)*SQRT(1+(G14)^2), 0.000001))^(2/3), 0.000001)))^2 -> 0.0034413494 | S14: =ABS(ABS(K14)/MAX(((F14)+(G14)*(L14))*(L14), 0.000001))/SQRT('1D'!$I$5*MAX((((F14)+(G14)*(L14))*(L14))/MAX((F14)+2*(G14)*(L14), 0.000001), 0.000001)) -> 1 | T14: =((F14)*(L14)^2)/2+(G14)*(L14)^3/3+(ABS(K14)^2)/('1D'!$I$5*MAX(((F14)+(G14)*(L14))*(L14), 0.000001)) -> 34.059203 | U14: =IF($A$2=0, 0, IFERROR(Q13-(((R13+R14)/2)*J14)-(IF(O13>O14, '1D'!$D$8*((O13^2-O14^2)/(2*'1D'!$I$5)), '1D'!$D$9*((O14^2-O13^2)/(2*'1D'!$I$5)))+('1D'!$D$10*(ABS(I14)/90)*(MAX(O13^2, O14^2)/(2*'1D'!$I$5))))-Q14, 0)) -> -0.0011500587 | V14: =IF($A$2=0, 1, IF(IFERROR(V13, 0)=0, 0, IFERROR(IF(ROUND(S14, 3)=1, 1, IF(AND(ABS(U14)<'1D'!$D$19, S14>1), 1, 0)), 0))) -> 1 | W14: =IF($A$2=0, MAX(MAX('1D'!$D$16, MAX('1D'!$D$16, POWER((ABS(K14)^2)/('1D'!$I$5*MAX(F14, 0.1)^2), 1/3))), IFERROR(W21, MAX(MAX('1D'!$D$16, MAX('1D'!$D$16, POWER((ABS(K14)^2)/('1D'!$I$5*MAX(F14, 0.1)^2), 1/3))), ($L$2)-E21))), IF(IFERROR(AG15, 0)=0, MAX(MAX('1D'!$D$16, MAX('1D'!$D$16, POWER((ABS(K14)^2)/('1D'!$I$5*MAX(F14, 0.1)^2), 1/3))), IFERROR(W21, MAX(MAX('1D'!$D$16, MAX('1D'!$D$16, POWER((ABS(K14)^2)/('1D'!$I$5*MAX(F14, 0.1)^2), 1/3))), ($L$2)-E21))), IF(IFERROR(W14, 0)=0, MAX(MAX('1D'!$D$16, MAX('1D'!$D$16, POWER((ABS(K14)^2)/('1D'!$I$5*MAX(F14, 0.1)^2), 1/3))), IFERROR(W21, MAX(MAX('1D'!$D$16, MAX('1D'!$D$16, POWER((ABS(K14)^2)/('1D'!$I$5*MAX(F14, 0.1)^2), 1/3))), ($L$2)-E21))), IF(OR(IFERROR(AD14, 0)>=1, IFERROR(AD15, 0)>=1), MAX('1D'!$D$16, MAX('1D'!$D$16, POWER((ABS(K14)^2)/('1D'!$I$5*MAX(F14, 0.1)^2), 1/3))), IF(ABS(IFERROR(AF14, 0))<'1D'!$D$19, MAX(MAX('1D'!$D$16, MAX('1D'!$D$16, POWER((ABS(K14)^2)/('1D'!$I$5*MAX(F14, 0.1)^2), 1/3))), IFERROR(W14, 0)), MAX(MAX('1D'!$D$16, MAX('1D'!$D$16, POWER((ABS(K14)^2)/('1D'!$I$5*MAX(F14, 0.1)^2), 1/3))), (IFERROR(W14, 0))+((IFERROR(AF14, 0))*'1D'!$D$18))))))) -> 2.6278332 | X14: =((F14)+(G14)*(W14))*(W14) -> 15.780138 | Y14: =(((F14)+(G14)*(W14))*(W14))/MAX((F14)+2*(W14)*SQRT(1+(G14)^2), 0.000001) -> 1.4013503 | Z14: =ABS(K14)/MAX(((F14)+(G14)*(W14))*(W14), 0.000001) -> 3.2319108 | AA14: =E14+W14 -> 636.93983 | AB14: =AA14+((ABS(K14)/MAX(((F14)+(G14)*(W14))*(W14), 0.000001))^2)/(2*'1D'!$I$5) -> 637.47221 | AC14: =((ABS(K14)*'1D'!$D$6)/(MAX(((F14)+(G14)*(W14))*(W14), 0.000001)*MAX(((((F14)+(G14)*(W14))*(W14))/MAX((F14)+2*(W14)*SQRT(1+(G14)^2), 0.000001))^(2/3), 0.000001)))^2 -> 0.0014986687 | AD14: =ABS(ABS(K14)/MAX(((F14)+(G14)*(W14))*(W14), 0.000001))/SQRT('1D'!$I$5*MAX((((F14)+(G14)*(W14))*(W14))/MAX((F14)+2*(G14)*(W14), 0.000001), 0.000001)) -> 0.6365404 | AE14: =((F14)*(W14)^2)/2+(G14)*(W14)^3/3+(ABS(K14)^2)/('1D'!$I$5*MAX(((F14)+(G14)*(W14))*(W14), 0.000001)) -> 37.535768 | AF14: =IF($A$2=0, 0, IFERROR(AB15+(((AC14+AC15)/2)*J15)+(IF(Z14>Z15, '1D'!$D$8*((Z14^2-Z15^2)/(2*'1D'!$I$5)), '1D'!$D$9*((Z15^2-Z14^2)/(2*'1D'!$I$5)))+('1D'!$D$10*(ABS(I15)/90)*(MAX(Z14^2, Z15^2)/(2*'1D'!$I$5))))-AB14, 0)) -> -0.00097318784 | AG14: =IF($A$2=0, 1, IF(IFERROR(AG15, 0)=0, 0, IFERROR(IF(OR(ROUND(AD14, 3)>=1, AND(ABS(AF14)<'1D'!$D$19, AD14<1)), 1, 0), 0))) -> 1 | AH14: =IFERROR(IF('1D'!V31="Supercritical", MAX('1D'!$D$16, IFERROR(L14, MAX('1D'!$D$16, POWER((ABS(K14)^2)/('1D'!$I$5*MAX(F14, 0.1)^2), 1/3)))), IF('1D'!V31="Subcritical", MAX('1D'!$D$16, IFERROR(W14, MAX('1D'!$D$16, POWER((ABS(K14)^2)/('1D'!$I$5*MAX(F14, 0.1)^2), 1/3)))), IF(IFERROR(T14, -1E+99)>=IFERROR(AE14, -1E+99), MAX('1D'!$D$16, IFERROR(L14, MAX('1D'!$D$16, POWER((ABS(K14)^2)/('1D'!$I$5*MAX(F14, 0.1)^2), 1/3)))), MAX('1D'!$D$16, IFERROR(W14, MAX('1D'!$D$16, POWER((ABS(K14)^2)/('1D'!$I$5*MAX(F14, 0.1)^2), 1/3))))))), MAX('1D'!$D$16, POWER((ABS(K14)^2)/('1D'!$I$5*MAX(F14, 0.1)^2), 1/3))) -> 2.6278332 | AI14: =E14+AH14 -> 636.93983 | AJ14: =AI14+((ABS(K14)/MAX(((F14)+(G14)*(AH14))*(AH14), 0.000001))^2)/(2*'1D'!$I$5) -> 637.47221 | AM14: 0 | AN14: 0 | AO14: =AM14+AN14 -> 0 | AP14: =AP13+AO14 -> 0 | AQ14: =ABS(ABS(K14)/MAX(((F14)+(G14)*(AH14))*(AH14), 0.000001))/SQRT('1D'!$I$5*MAX((((F14)+(G14)*(AH14))*(AH14))/MAX((F14)+2*(G14)*(AH14), 0.000001), 0.000001)) -> 0.6365404 | AR14: =IF(AQ14<1, "Subcritical", "Supercritical") -> Subcritical | AS14: =((ABS(K14)*'1D'!$D$6)/(MAX(((F14)+(G14)*(AH14))*(AH14), 0.000001)*MAX(((((F14)+(G14)*(AH14))*(AH14))/MAX((F14)+2*(AH14)*SQRT(1+(G14)^2), 0.000001))^(2/3), 0.000001)))^2 -> 0.0014986687
A15: 6 | B15: 5.001 | C15: 616558.71 | D15: 3097765.5 | E15: 634.31 | F15: 6.005 | G15: 0 | H15: Normal | I15: 0 | J15: =B15-B14 -> 1.001 | K15: =MAX(0, K14-AO14) -> 51 | L15: =IF($A$2=0, IFERROR(L14, MAX('1D'!$D$16, POWER((ABS(K15)^2)/('1D'!$I$5*MAX(F15, 0.1)^2), 1/3))), IF(IFERROR(V14, 0)=0, IFERROR(L14, MAX('1D'!$D$16, POWER((ABS(K15)^2)/('1D'!$I$5*MAX(F15, 0.1)^2), 1/3))), IF(OR(IFERROR(L15, 0)=0, IFERROR(S14, 0)<1, IFERROR(S15, 0)<1), MAX('1D'!$D$16, POWER((ABS(K15)^2)/('1D'!$I$5*MAX(F15, 0.1)^2), 1/3)), IF(IFERROR(U15, 0)>0, MAX('1D'!$D$16, IFERROR(L15, 0)+((IFERROR(U15, 0))*'1D'!$D$18*IF((IFERROR(S15, 0))<1, 1, -1))), IF(IFERROR(U15, 0)<0, IF(ABS((MAX('1D'!$D$16, POWER((ABS(K15)^2)/('1D'!$I$5*MAX(F15, 0.1)^2), 1/3)))-IFERROR(L15, 0))>'1D'!$D$19, MAX('1D'!$D$16, IF((MAX('1D'!$D$16, POWER((ABS(K15)^2)/('1D'!$I$5*MAX(F15, 0.1)^2), 1/3)))>IFERROR(L15, 0), MIN((MAX('1D'!$D$16, POWER((ABS(K15)^2)/('1D'!$I$5*MAX(F15, 0.1)^2), 1/3))), IFERROR(L15, 0)+(MIN(ABS(IFERROR(U15, 0))*'1D'!$D$18, ABS((MAX('1D'!$D$16, POWER((ABS(K15)^2)/('1D'!$I$5*MAX(F15, 0.1)^2), 1/3)))-IFERROR(L15, 0))))), MAX((MAX('1D'!$D$16, POWER((ABS(K15)^2)/('1D'!$I$5*MAX(F15, 0.1)^2), 1/3))), IFERROR(L15, 0)-(MIN(ABS(IFERROR(U15, 0))*'1D'!$D$18, ABS((MAX('1D'!$D$16, POWER((ABS(K15)^2)/('1D'!$I$5*MAX(F15, 0.1)^2), 1/3)))-IFERROR(L15, 0))))))), MAX('1D'!$D$16, POWER((ABS(K15)^2)/('1D'!$I$5*MAX(F15, 0.1)^2), 1/3))), MAX('1D'!$D$16, IFERROR(L15, 0))))))) -> 1.9445321 | M15: =((F15)+(G15)*(L15))*(L15) -> 11.676915 | N15: =(((F15)+(G15)*(L15))*(L15))/MAX((F15)+2*(L15)*SQRT(1+(G15)^2), 0.000001) -> 1.180194 | O15: =ABS(K15)/MAX(((F15)+(G15)*(L15))*(L15), 0.000001) -> 4.367592 | P15: =E15+L15 -> 636.25453 | Q15: =P15+((ABS(K15)/MAX(((F15)+(G15)*(L15))*(L15), 0.000001))^2)/(2*'1D'!$I$5) -> 637.2268 | R15: =((ABS(K15)*'1D'!$D$6)/(MAX(((F15)+(G15)*(L15))*(L15), 0.000001)*MAX(((((F15)+(G15)*(L15))*(L15))/MAX((F15)+2*(L15)*SQRT(1+(G15)^2), 0.000001))^(2/3), 0.000001)))^2 -> 0.0034413494 | S15: =ABS(ABS(K15)/MAX(((F15)+(G15)*(L15))*(L15), 0.000001))/SQRT('1D'!$I$5*MAX((((F15)+(G15)*(L15))*(L15))/MAX((F15)+2*(G15)*(L15), 0.000001), 0.000001)) -> 1 | T15: =((F15)*(L15)^2)/2+(G15)*(L15)^3/3+(ABS(K15)^2)/('1D'!$I$5*MAX(((F15)+(G15)*(L15))*(L15), 0.000001)) -> 34.059203 | U15: =IF($A$2=0, 0, IFERROR(Q14-(((R14+R15)/2)*J15)-(IF(O14>O15, '1D'!$D$8*((O14^2-O15^2)/(2*'1D'!$I$5)), '1D'!$D$9*((O15^2-O14^2)/(2*'1D'!$I$5)))+('1D'!$D$10*(ABS(I15)/90)*(MAX(O14^2, O15^2)/(2*'1D'!$I$5))))-Q15, 0)) -> -0.0014447907 | V15: =IF($A$2=0, 1, IF(IFERROR(V14, 0)=0, 0, IFERROR(IF(ROUND(S15, 3)=1, 1, IF(AND(ABS(U15)<'1D'!$D$19, S15>1), 1, 0)), 0))) -> 1 | W15: =IF($A$2=0, MAX(MAX('1D'!$D$16, MAX('1D'!$D$16, POWER((ABS(K15)^2)/('1D'!$I$5*MAX(F15, 0.1)^2), 1/3))), IFERROR(W21, MAX(MAX('1D'!$D$16, MAX('1D'!$D$16, POWER((ABS(K15)^2)/('1D'!$I$5*MAX(F15, 0.1)^2), 1/3))), ($L$2)-E21))), IF(IFERROR(AG16, 0)=0, MAX(MAX('1D'!$D$16, MAX('1D'!$D$16, POWER((ABS(K15)^2)/('1D'!$I$5*MAX(F15, 0.1)^2), 1/3))), IFERROR(W21, MAX(MAX('1D'!$D$16, MAX('1D'!$D$16, POWER((ABS(K15)^2)/('1D'!$I$5*MAX(F15, 0.1)^2), 1/3))), ($L$2)-E21))), IF(IFERROR(W15, 0)=0, MAX(MAX('1D'!$D$16, MAX('1D'!$D$16, POWER((ABS(K15)^2)/('1D'!$I$5*MAX(F15, 0.1)^2), 1/3))), IFERROR(W21, MAX(MAX('1D'!$D$16, MAX('1D'!$D$16, POWER((ABS(K15)^2)/('1D'!$I$5*MAX(F15, 0.1)^2), 1/3))), ($L$2)-E21))), IF(OR(IFERROR(AD15, 0)>=1, IFERROR(AD16, 0)>=1), MAX('1D'!$D$16, MAX('1D'!$D$16, POWER((ABS(K15)^2)/('1D'!$I$5*MAX(F15, 0.1)^2), 1/3))), IF(ABS(IFERROR(AF15, 0))<'1D'!$D$19, MAX(MAX('1D'!$D$16, MAX('1D'!$D$16, POWER((ABS(K15)^2)/('1D'!$I$5*MAX(F15, 0.1)^2), 1/3))), IFERROR(W15, 0)), MAX(MAX('1D'!$D$16, MAX('1D'!$D$16, POWER((ABS(K15)^2)/('1D'!$I$5*MAX(F15, 0.1)^2), 1/3))), (IFERROR(W15, 0))+((IFERROR(AF15, 0))*'1D'!$D$18))))))) -> 2.6269777 | X15: =((F15)+(G15)*(W15))*(W15) -> 15.775001 | Y15: =(((F15)+(G15)*(W15))*(W15))/MAX((F15)+2*(W15)*SQRT(1+(G15)^2), 0.000001) -> 1.401107 | Z15: =ABS(K15)/MAX(((F15)+(G15)*(W15))*(W15), 0.000001) -> 3.2329633 | AA15: =E15+W15 -> 636.93698 | AB15: =AA15+((ABS(K15)/MAX(((F15)+(G15)*(W15))*(W15), 0.000001))^2)/(2*'1D'!$I$5) -> 637.4697 | AC15: =((ABS(K15)*'1D'!$D$6)/(MAX(((F15)+(G15)*(W15))*(W15), 0.000001)*MAX(((((F15)+(G15)*(W15))*(W15))/MAX((F15)+2*(W15)*SQRT(1+(G15)^2), 0.000001))^(2/3), 0.000001)))^2 -> 0.0014999923 | AD15: =ABS(ABS(K15)/MAX(((F15)+(G15)*(W15))*(W15), 0.000001))/SQRT('1D'!$I$5*MAX((((F15)+(G15)*(W15))*(W15))/MAX((F15)+2*(G15)*(W15), 0.000001), 0.000001)) -> 0.63685137 | AE15: =((F15)*(W15)^2)/2+(G15)*(W15)^3/3+(ABS(K15)^2)/('1D'!$I$5*MAX(((F15)+(G15)*(W15))*(W15), 0.000001)) -> 37.527742 | AF15: =IF($A$2=0, 0, IFERROR(AB16+(((AC15+AC16)/2)*J16)+(IF(Z15>Z16, '1D'!$D$8*((Z15^2-Z16^2)/(2*'1D'!$I$5)), '1D'!$D$9*((Z16^2-Z15^2)/(2*'1D'!$I$5)))+('1D'!$D$10*(ABS(I16)/90)*(MAX(Z15^2, Z16^2)/(2*'1D'!$I$5))))-AB15, 0)) -> -0.00098633948 | AG15: =IF($A$2=0, 1, IF(IFERROR(AG16, 0)=0, 0, IFERROR(IF(OR(ROUND(AD15, 3)>=1, AND(ABS(AF15)<'1D'!$D$19, AD15<1)), 1, 0), 0))) -> 1 | AH15: =IFERROR(IF('1D'!V31="Supercritical", MAX('1D'!$D$16, IFERROR(L15, MAX('1D'!$D$16, POWER((ABS(K15)^2)/('1D'!$I$5*MAX(F15, 0.1)^2), 1/3)))), IF('1D'!V31="Subcritical", MAX('1D'!$D$16, IFERROR(W15, MAX('1D'!$D$16, POWER((ABS(K15)^2)/('1D'!$I$5*MAX(F15, 0.1)^2), 1/3)))), IF(IFERROR(T15, -1E+99)>=IFERROR(AE15, -1E+99), MAX('1D'!$D$16, IFERROR(L15, MAX('1D'!$D$16, POWER((ABS(K15)^2)/('1D'!$I$5*MAX(F15, 0.1)^2), 1/3)))), MAX('1D'!$D$16, IFERROR(W15, MAX('1D'!$D$16, POWER((ABS(K15)^2)/('1D'!$I$5*MAX(F15, 0.1)^2), 1/3))))))), MAX('1D'!$D$16, POWER((ABS(K15)^2)/('1D'!$I$5*MAX(F15, 0.1)^2), 1/3))) -> 2.6269777 | AI15: =E15+AH15 -> 636.93698 | AJ15: =AI15+((ABS(K15)/MAX(((F15)+(G15)*(AH15))*(AH15), 0.000001))^2)/(2*'1D'!$I$5) -> 637.4697 | AM15: 0 | AN15: 0 | AO15: =AM15+AN15 -> 0 | AP15: =AP14+AO15 -> 0 | AQ15: =ABS(ABS(K15)/MAX(((F15)+(G15)*(AH15))*(AH15), 0.000001))/SQRT('1D'!$I$5*MAX((((F15)+(G15)*(AH15))*(AH15))/MAX((F15)+2*(G15)*(AH15), 0.000001), 0.000001)) -> 0.63685137 | AR15: =IF(AQ15<1, "Subcritical", "Supercritical") -> Subcritical | AS15: =((ABS(K15)*'1D'!$D$6)/(MAX(((F15)+(G15)*(AH15))*(AH15), 0.000001)*MAX(((((F15)+(G15)*(AH15))*(AH15))/MAX((F15)+2*(AH15)*SQRT(1+(G15)^2), 0.000001))^(2/3), 0.000001)))^2 -> 0.0014999923
A16: 7 | B16: 6.001 | C16: 616558.24 | D16: 3097764.6 | E16: 634.308 | F16: 6.006 | G16: 0 | H16: Normal | I16: 0.027 | J16: =B16-B15 -> 1 | K16: =MAX(0, K15-AO15) -> 51 | L16: =IF($A$2=0, IFERROR(L15, MAX('1D'!$D$16, POWER((ABS(K16)^2)/('1D'!$I$5*MAX(F16, 0.1)^2), 1/3))), IF(IFERROR(V15, 0)=0, IFERROR(L15, MAX('1D'!$D$16, POWER((ABS(K16)^2)/('1D'!$I$5*MAX(F16, 0.1)^2), 1/3))), IF(OR(IFERROR(L16, 0)=0, IFERROR(S15, 0)<1, IFERROR(S16, 0)<1), MAX('1D'!$D$16, POWER((ABS(K16)^2)/('1D'!$I$5*MAX(F16, 0.1)^2), 1/3)), IF(IFERROR(U16, 0)>0, MAX('1D'!$D$16, IFERROR(L16, 0)+((IFERROR(U16, 0))*'1D'!$D$18*IF((IFERROR(S16, 0))<1, 1, -1))), IF(IFERROR(U16, 0)<0, IF(ABS((MAX('1D'!$D$16, POWER((ABS(K16)^2)/('1D'!$I$5*MAX(F16, 0.1)^2), 1/3)))-IFERROR(L16, 0))>'1D'!$D$19, MAX('1D'!$D$16, IF((MAX('1D'!$D$16, POWER((ABS(K16)^2)/('1D'!$I$5*MAX(F16, 0.1)^2), 1/3)))>IFERROR(L16, 0), MIN((MAX('1D'!$D$16, POWER((ABS(K16)^2)/('1D'!$I$5*MAX(F16, 0.1)^2), 1/3))), IFERROR(L16, 0)+(MIN(ABS(IFERROR(U16, 0))*'1D'!$D$18, ABS((MAX('1D'!$D$16, POWER((ABS(K16)^2)/('1D'!$I$5*MAX(F16, 0.1)^2), 1/3)))-IFERROR(L16, 0))))), MAX((MAX('1D'!$D$16, POWER((ABS(K16)^2)/('1D'!$I$5*MAX(F16, 0.1)^2), 1/3))), IFERROR(L16, 0)-(MIN(ABS(IFERROR(U16, 0))*'1D'!$D$18, ABS((MAX('1D'!$D$16, POWER((ABS(K16)^2)/('1D'!$I$5*MAX(F16, 0.1)^2), 1/3)))-IFERROR(L16, 0))))))), MAX('1D'!$D$16, POWER((ABS(K16)^2)/('1D'!$I$5*MAX(F16, 0.1)^2), 1/3))), MAX('1D'!$D$16, IFERROR(L16, 0))))))) -> 1.9443162 | M16: =((F16)+(G16)*(L16))*(L16) -> 11.677563 | N16: =(((F16)+(G16)*(L16))*(L16))/MAX((F16)+2*(L16)*SQRT(1+(G16)^2), 0.000001) -> 1.1801917 | O16: =ABS(K16)/MAX(((F16)+(G16)*(L16))*(L16), 0.000001) -> 4.3673495 | P16: =E16+L16 -> 636.25232 | Q16: =P16+((ABS(K16)/MAX(((F16)+(G16)*(L16))*(L16), 0.000001))^2)/(2*'1D'!$I$5) -> 637.22447 | R16: =((ABS(K16)*'1D'!$D$6)/(MAX(((F16)+(G16)*(L16))*(L16), 0.000001)*MAX(((((F16)+(G16)*(L16))*(L16))/MAX((F16)+2*(L16)*SQRT(1+(G16)^2), 0.000001))^(2/3), 0.000001)))^2 -> 0.0034409763 | S16: =ABS(ABS(K16)/MAX(((F16)+(G16)*(L16))*(L16), 0.000001))/SQRT('1D'!$I$5*MAX((((F16)+(G16)*(L16))*(L16))/MAX((F16)+2*(G16)*(L16), 0.000001), 0.000001)) -> 1 | T16: =((F16)*(L16)^2)/2+(G16)*(L16)^3/3+(ABS(K16)^2)/('1D'!$I$5*MAX(((F16)+(G16)*(L16))*(L16), 0.000001)) -> 34.057313 | U16: =IF($A$2=0, 0, IFERROR(Q15-(((R15+R16)/2)*J16)-(IF(O15>O16, '1D'!$D$8*((O15^2-O16^2)/(2*'1D'!$I$5)), '1D'!$D$9*((O16^2-O15^2)/(2*'1D'!$I$5)))+('1D'!$D$10*(ABS(I16)/90)*(MAX(O15^2, O16^2)/(2*'1D'!$I$5))))-Q16, 0)) -> -0.0011935183 | V16: =IF($A$2=0, 1, IF(IFERROR(V15, 0)=0, 0, IFERROR(IF(ROUND(S16, 3)=1, 1, IF(AND(ABS(U16)<'1D'!$D$19, S16>1), 1, 0)), 0))) -> 1 | W16: =IF($A$2=0, MAX(MAX('1D'!$D$16, MAX('1D'!$D$16, POWER((ABS(K16)^2)/('1D'!$I$5*MAX(F16, 0.1)^2), 1/3))), IFERROR(W21, MAX(MAX('1D'!$D$16, MAX('1D'!$D$16, POWER((ABS(K16)^2)/('1D'!$I$5*MAX(F16, 0.1)^2), 1/3))), ($L$2)-E21))), IF(IFERROR(AG17, 0)=0, MAX(MAX('1D'!$D$16, MAX('1D'!$D$16, POWER((ABS(K16)^2)/('1D'!$I$5*MAX(F16, 0.1)^2), 1/3))), IFERROR(W21, MAX(MAX('1D'!$D$16, MAX('1D'!$D$16, POWER((ABS(K16)^2)/('1D'!$I$5*MAX(F16, 0.1)^2), 1/3))), ($L$2)-E21))), IF(IFERROR(W16, 0)=0, MAX(MAX('1D'!$D$16, MAX('1D'!$D$16, POWER((ABS(K16)^2)/('1D'!$I$5*MAX(F16, 0.1)^2), 1/3))), IFERROR(W21, MAX(MAX('1D'!$D$16, MAX('1D'!$D$16, POWER((ABS(K16)^2)/('1D'!$I$5*MAX(F16, 0.1)^2), 1/3))), ($L$2)-E21))), IF(OR(IFERROR(AD16, 0)>=1, IFERROR(AD17, 0)>=1), MAX('1D'!$D$16, MAX('1D'!$D$16, POWER((ABS(K16)^2)/('1D'!$I$5*MAX(F16, 0.1)^2), 1/3))), IF(ABS(IFERROR(AF16, 0))<'1D'!$D$19, MAX(MAX('1D'!$D$16, MAX('1D'!$D$16, POWER((ABS(K16)^2)/('1D'!$I$5*MAX(F16, 0.1)^2), 1/3))), IFERROR(W16, 0)), MAX(MAX('1D'!$D$16, MAX('1D'!$D$16, POWER((ABS(K16)^2)/('1D'!$I$5*MAX(F16, 0.1)^2), 1/3))), (IFERROR(W16, 0))+((IFERROR(AF16, 0))*'1D'!$D$18))))))) -> 2.6264084 | X16: =((F16)+(G16)*(W16))*(W16) -> 15.774209 | Y16: =(((F16)+(G16)*(W16))*(W16))/MAX((F16)+2*(W16)*SQRT(1+(G16)^2), 0.000001) -> 1.4010539 | Z16: =ABS(K16)/MAX(((F16)+(G16)*(W16))*(W16), 0.000001) -> 3.2331257 | AA16: =E16+W16 -> 636.93441 | AB16: =AA16+((ABS(K16)/MAX(((F16)+(G16)*(W16))*(W16), 0.000001))^2)/(2*'1D'!$I$5) -> 637.46719 | AC16: =((ABS(K16)*'1D'!$D$6)/(MAX(((F16)+(G16)*(W16))*(W16), 0.000001)*MAX(((((F16)+(G16)*(W16))*(W16))/MAX((F16)+2*(W16)*SQRT(1+(G16)^2), 0.000001))^(2/3), 0.000001)))^2 -> 0.0015002187 | AD16: =ABS(ABS(K16)/MAX(((F16)+(G16)*(W16))*(W16), 0.000001))/SQRT('1D'!$I$5*MAX((((F16)+(G16)*(W16))*(W16))/MAX((F16)+2*(G16)*(W16), 0.000001), 0.000001)) -> 0.63695236 | AE16: =((F16)*(W16)^2)/2+(G16)*(W16)^3/3+(ABS(K16)^2)/('1D'!$I$5*MAX(((F16)+(G16)*(W16))*(W16), 0.000001)) -> 37.523056 | AF16: =IF($A$2=0, 0, IFERROR(AB17+(((AC16+AC17)/2)*J17)+(IF(Z16>Z17, '1D'!$D$8*((Z16^2-Z17^2)/(2*'1D'!$I$5)), '1D'!$D$9*((Z17^2-Z16^2)/(2*'1D'!$I$5)))+('1D'!$D$10*(ABS(I17)/90)*(MAX(Z16^2, Z17^2)/(2*'1D'!$I$5))))-AB16, 0)) -> -0.00099432189 | AG16: =IF($A$2=0, 1, IF(IFERROR(AG17, 0)=0, 0, IFERROR(IF(OR(ROUND(AD16, 3)>=1, AND(ABS(AF16)<'1D'!$D$19, AD16<1)), 1, 0), 0))) -> 1 | AH16: =IFERROR(IF('1D'!V31="Supercritical", MAX('1D'!$D$16, IFERROR(L16, MAX('1D'!$D$16, POWER((ABS(K16)^2)/('1D'!$I$5*MAX(F16, 0.1)^2), 1/3)))), IF('1D'!V31="Subcritical", MAX('1D'!$D$16, IFERROR(W16, MAX('1D'!$D$16, POWER((ABS(K16)^2)/('1D'!$I$5*MAX(F16, 0.1)^2), 1/3)))), IF(IFERROR(T16, -1E+99)>=IFERROR(AE16, -1E+99), MAX('1D'!$D$16, IFERROR(L16, MAX('1D'!$D$16, POWER((ABS(K16)^2)/('1D'!$I$5*MAX(F16, 0.1)^2), 1/3)))), MAX('1D'!$D$16, IFERROR(W16, MAX('1D'!$D$16, POWER((ABS(K16)^2)/('1D'!$I$5*MAX(F16, 0.1)^2), 1/3))))))), MAX('1D'!$D$16, POWER((ABS(K16)^2)/('1D'!$I$5*MAX(F16, 0.1)^2), 1/3))) -> 2.6264084 | AI16: =E16+AH16 -> 636.93441 | AJ16: =AI16+((ABS(K16)/MAX(((F16)+(G16)*(AH16))*(AH16), 0.000001))^2)/(2*'1D'!$I$5) -> 637.46719 | AM16: 0 | AN16: 0 | AO16: =AM16+AN16 -> 0 | AP16: =AP15+AO16 -> 0 | AQ16: =ABS(ABS(K16)/MAX(((F16)+(G16)*(AH16))*(AH16), 0.000001))/SQRT('1D'!$I$5*MAX((((F16)+(G16)*(AH16))*(AH16))/MAX((F16)+2*(G16)*(AH16), 0.000001), 0.000001)) -> 0.63695236 | AR16: =IF(AQ16<1, "Subcritical", "Supercritical") -> Subcritical | AS16: =((ABS(K16)*'1D'!$D$6)/(MAX(((F16)+(G16)*(AH16))*(AH16), 0.000001)*MAX(((((F16)+(G16)*(AH16))*(AH16))/MAX((F16)+2*(AH16)*SQRT(1+(G16)^2), 0.000001))^(2/3), 0.000001)))^2 -> 0.0015002187
